2021-08-26 14:31:39,321    5684     INFO test_runner.py(156) - 预计并发线程数：1
2021-08-26 14:31:39,323   16244     INFO result.py(69) - 开始测试： test_applyClient用户资料提交 (Test_Case.test_运营用户创建审批.Test_新建用户)
2021-08-26 14:31:39,323   16244     INFO test_运营用户创建审批.py(23) - 初始化 Session
2021-08-26 14:31:40,011   16244     INFO test_运营用户创建审批.py(18) - 关闭 Session
2021-08-26 14:31:40,011   16244     INFO result.py(156) - 测试执行通过： test_applyClient用户资料提交 (Test_Case.test_运营用户创建审批.Test_新建用户)
2021-08-26 14:31:40,026   16244     INFO result.py(90) - 测试结束： test_applyClient用户资料提交 (Test_Case.test_运营用户创建审批.Test_新建用户)
2021-08-26 14:31:40,026   16244     INFO result.py(91) - 耗时： 0.7031576633453369
2021-08-26 14:31:40,027   16244     INFO result.py(69) - 开始测试： test_submitAudit提交审核 (Test_Case.test_运营用户创建审批.Test_新建用户)
2021-08-26 14:31:40,027   16244     INFO test_运营用户创建审批.py(197) - 初始化 Session
2021-08-26 14:31:40,324   16244     INFO test_运营用户创建审批.py(18) - 关闭 Session
2021-08-26 14:31:40,324   16244  WARNING result.py(190) - 测试未通过： test_submitAudit提交审核 (Test_Case.test_运营用户创建审批.Test_新建用户)
Traceback (most recent call last):
  File "F:\python\EDDID_CDMS\Test_Case\test_运营用户创建审批.py", line 221, in test_submitAudit提交审核
    self.assertEqual("操作成功", r.json().get("msg"))
AssertionError: '操作成功' != '错误码:[MAS_01103],客户信息为空。'
- 操作成功
+ 错误码:[MAS_01103],客户信息为空。


2021-08-26 14:31:40,324   16244     INFO result.py(90) - 测试结束： test_submitAudit提交审核 (Test_Case.test_运营用户创建审批.Test_新建用户)
2021-08-26 14:31:40,324   16244     INFO result.py(91) - 耗时： 0.2972099781036377
2021-08-26 14:31:40,325    5684     INFO test_runner.py(193) - 
Pass	test_applyClient用户资料提交 (Test_Case.test_运营用户创建审批.Test_新建用户)

2021-08-26 14:31:40,325    5684    ERROR test_runner.py(195) - 
Fail	test_submitAudit提交审核 (Test_Case.test_运营用户创建审批.Test_新建用户)

2021-08-26 14:31:40,327    5684     INFO test_runner.py(213) - 
测试结束！
运行时间: 0:00:01.266436
共计执行用例数量：2
执行成功用例数量：1
执行失败用例数量：1
跳过执行用例数量：0
产生异常用例数量：0

2021-08-26 14:33:51,340   16344     INFO test_runner.py(156) - 预计并发线程数：1
2021-08-26 14:33:51,342   14132     INFO result.py(69) - 开始测试： test_applyClient用户资料提交 (Test_Case.test_运营用户创建审批.Test_新建用户)
2021-08-26 14:33:51,342   14132     INFO test_运营用户创建审批.py(23) - 初始化 Session
2021-08-26 14:33:51,985   14132     INFO test_运营用户创建审批.py(18) - 关闭 Session
2021-08-26 14:33:51,999   14132     INFO result.py(156) - 测试执行通过： test_applyClient用户资料提交 (Test_Case.test_运营用户创建审批.Test_新建用户)
2021-08-26 14:33:51,999   14132     INFO result.py(90) - 测试结束： test_applyClient用户资料提交 (Test_Case.test_运营用户创建审批.Test_新建用户)
2021-08-26 14:33:52,015   14132     INFO result.py(91) - 耗时： 0.6572399139404297
2021-08-26 14:33:52,015   14132     INFO result.py(69) - 开始测试： test_submitAudit提交审核 (Test_Case.test_运营用户创建审批.Test_新建用户)
2021-08-26 14:33:52,015   14132     INFO test_运营用户创建审批.py(197) - 初始化 Session
2021-08-26 14:33:52,313   14132     INFO test_运营用户创建审批.py(18) - 关闭 Session
2021-08-26 14:33:52,313   14132  WARNING result.py(190) - 测试未通过： test_submitAudit提交审核 (Test_Case.test_运营用户创建审批.Test_新建用户)
Traceback (most recent call last):
  File "F:\python\EDDID_CDMS\Test_Case\test_运营用户创建审批.py", line 221, in test_submitAudit提交审核
    self.assertEqual("操作成功", r.json().get("msg"))
AssertionError: '操作成功' != '系统繁忙'
- 操作成功
+ 系统繁忙


2021-08-26 14:33:52,314   14132     INFO result.py(90) - 测试结束： test_submitAudit提交审核 (Test_Case.test_运营用户创建审批.Test_新建用户)
2021-08-26 14:33:52,314   14132     INFO result.py(91) - 耗时： 0.29743528366088867
2021-08-26 14:33:52,314   16344     INFO test_runner.py(193) - 
Pass	test_applyClient用户资料提交 (Test_Case.test_运营用户创建审批.Test_新建用户)

2021-08-26 14:33:52,314   16344    ERROR test_runner.py(195) - 
Fail	test_submitAudit提交审核 (Test_Case.test_运营用户创建审批.Test_新建用户)

2021-08-26 14:33:52,315   16344     INFO test_runner.py(213) - 
测试结束！
运行时间: 0:00:01.251146
共计执行用例数量：2
执行成功用例数量：1
执行失败用例数量：1
跳过执行用例数量：0
产生异常用例数量：0

2021-08-26 14:52:46,125   21572     INFO test_runner.py(156) - 预计并发线程数：1
2021-08-26 14:52:46,126   11668     INFO result.py(69) - 开始测试： test_applyClient用户资料提交 (Test_Case.test_运营用户创建审批.Test_新建用户)
2021-08-26 14:52:46,126   11668     INFO test_运营用户创建审批.py(23) - 初始化 Session
2021-08-26 14:52:46,572   11668     INFO test_运营用户创建审批.py(18) - 关闭 Session
2021-08-26 14:52:46,588   11668     INFO result.py(156) - 测试执行通过： test_applyClient用户资料提交 (Test_Case.test_运营用户创建审批.Test_新建用户)
2021-08-26 14:52:46,588   11668     INFO result.py(90) - 测试结束： test_applyClient用户资料提交 (Test_Case.test_运营用户创建审批.Test_新建用户)
2021-08-26 14:52:46,603   11668     INFO result.py(91) - 耗时： 0.4617950916290283
2021-08-26 14:52:46,603   11668     INFO result.py(69) - 开始测试： test_submitAudit提交审核 (Test_Case.test_运营用户创建审批.Test_新建用户)
2021-08-26 14:52:46,603   11668     INFO test_运营用户创建审批.py(197) - 初始化 Session
2021-08-26 14:52:46,723   11668     INFO test_运营用户创建审批.py(18) - 关闭 Session
2021-08-26 14:52:46,724   11668  WARNING result.py(190) - 测试未通过： test_submitAudit提交审核 (Test_Case.test_运营用户创建审批.Test_新建用户)
Traceback (most recent call last):
  File "F:\python\EDDID_CDMS\Test_Case\test_运营用户创建审批.py", line 222, in test_submitAudit提交审核
    self.assertEqual("操作成功", r.json().get("msg"))
AssertionError: '操作成功' != '错误码:[MAS_01103],客户信息为空。'
- 操作成功
+ 错误码:[MAS_01103],客户信息为空。


2021-08-26 14:52:46,724   11668     INFO result.py(90) - 测试结束： test_submitAudit提交审核 (Test_Case.test_运营用户创建审批.Test_新建用户)
2021-08-26 14:52:46,724   11668     INFO result.py(91) - 耗时： 0.12102246284484863
2021-08-26 14:52:46,724   21572     INFO test_runner.py(193) - 
Pass	test_applyClient用户资料提交 (Test_Case.test_运营用户创建审批.Test_新建用户)

2021-08-26 14:52:46,724   21572    ERROR test_runner.py(195) - 
Fail	test_submitAudit提交审核 (Test_Case.test_运营用户创建审批.Test_新建用户)

2021-08-26 14:52:46,725   21572     INFO test_runner.py(213) - 
测试结束！
运行时间: 0:00:00.805168
共计执行用例数量：2
执行成功用例数量：1
执行失败用例数量：1
跳过执行用例数量：0
产生异常用例数量：0

2021-08-26 14:54:22,819   10028     INFO test_runner.py(156) - 预计并发线程数：1
2021-08-26 14:54:22,822   19804     INFO result.py(69) - 开始测试： test_applyClient用户资料提交 (Test_Case.test_运营用户创建审批.Test_新建用户)
2021-08-26 14:54:22,822   19804     INFO test_运营用户创建审批.py(23) - 初始化 Session
2021-08-26 14:54:23,214   19804     INFO test_运营用户创建审批.py(18) - 关闭 Session
2021-08-26 14:54:23,230   19804     INFO result.py(156) - 测试执行通过： test_applyClient用户资料提交 (Test_Case.test_运营用户创建审批.Test_新建用户)
2021-08-26 14:54:23,230   19804     INFO result.py(90) - 测试结束： test_applyClient用户资料提交 (Test_Case.test_运营用户创建审批.Test_新建用户)
2021-08-26 14:54:23,230   19804     INFO result.py(91) - 耗时： 0.4089057445526123
2021-08-26 14:54:23,245   19804     INFO result.py(69) - 开始测试： test_submitAudit提交审核 (Test_Case.test_运营用户创建审批.Test_新建用户)
2021-08-26 14:54:23,245   19804     INFO test_运营用户创建审批.py(197) - 初始化 Session
2021-08-26 14:54:23,336   19804     INFO test_运营用户创建审批.py(209) - applyId为,applyId
2021-08-26 14:54:23,365   19804     INFO test_运营用户创建审批.py(18) - 关闭 Session
2021-08-26 14:54:23,366   19804  WARNING result.py(190) - 测试未通过： test_submitAudit提交审核 (Test_Case.test_运营用户创建审批.Test_新建用户)
Traceback (most recent call last):
  File "F:\python\EDDID_CDMS\Test_Case\test_运营用户创建审批.py", line 222, in test_submitAudit提交审核
    self.assertEqual("操作成功", r.json().get("msg"))
AssertionError: '操作成功' != '错误码:[MAS_01103],客户信息为空。'
- 操作成功
+ 错误码:[MAS_01103],客户信息为空。


2021-08-26 14:54:23,366   19804     INFO result.py(90) - 测试结束： test_submitAudit提交审核 (Test_Case.test_运营用户创建审批.Test_新建用户)
2021-08-26 14:54:23,366   19804     INFO result.py(91) - 耗时： 0.12095379829406738
2021-08-26 14:54:23,366   10028     INFO test_runner.py(193) - 
Pass	test_applyClient用户资料提交 (Test_Case.test_运营用户创建审批.Test_新建用户)

2021-08-26 14:54:23,366   10028    ERROR test_runner.py(195) - 
Fail	test_submitAudit提交审核 (Test_Case.test_运营用户创建审批.Test_新建用户)

2021-08-26 14:54:23,367   10028     INFO test_runner.py(213) - 
测试结束！
运行时间: 0:00:00.739929
共计执行用例数量：2
执行成功用例数量：1
执行失败用例数量：1
跳过执行用例数量：0
产生异常用例数量：0

2021-08-26 14:58:13,274   17744     INFO test_runner.py(156) - 预计并发线程数：1
2021-08-26 14:58:13,275    1032     INFO result.py(69) - 开始测试： test_applyClient用户资料提交 (Test_Case.test_运营用户创建审批.Test_新建用户)
2021-08-26 14:58:13,276    1032     INFO test_运营用户创建审批.py(23) - 初始化 Session
2021-08-26 14:58:13,780    1032     INFO test_运营用户创建审批.py(18) - 关闭 Session
2021-08-26 14:58:13,780    1032     INFO result.py(156) - 测试执行通过： test_applyClient用户资料提交 (Test_Case.test_运营用户创建审批.Test_新建用户)
2021-08-26 14:58:13,780    1032     INFO result.py(90) - 测试结束： test_applyClient用户资料提交 (Test_Case.test_运营用户创建审批.Test_新建用户)
2021-08-26 14:58:13,780    1032     INFO result.py(91) - 耗时： 0.5056798458099365
2021-08-26 14:58:13,796    1032     INFO result.py(69) - 开始测试： test_submitAudit提交审核 (Test_Case.test_运营用户创建审批.Test_新建用户)
2021-08-26 14:58:13,796    1032     INFO test_运营用户创建审批.py(197) - 初始化 Session
2021-08-26 14:58:13,887    1032     INFO test_运营用户创建审批.py(209) - 1147393
2021-08-26 14:58:13,919    1032     INFO test_运营用户创建审批.py(18) - 关闭 Session
2021-08-26 14:58:13,920    1032  WARNING result.py(190) - 测试未通过： test_submitAudit提交审核 (Test_Case.test_运营用户创建审批.Test_新建用户)
Traceback (most recent call last):
  File "F:\python\EDDID_CDMS\Test_Case\test_运营用户创建审批.py", line 222, in test_submitAudit提交审核
    self.assertEqual("操作成功", r.json().get("msg"))
AssertionError: '操作成功' != '错误码:[MAS_01103],客户信息为空。'
- 操作成功
+ 错误码:[MAS_01103],客户信息为空。


2021-08-26 14:58:13,920    1032     INFO result.py(90) - 测试结束： test_submitAudit提交审核 (Test_Case.test_运营用户创建审批.Test_新建用户)
2021-08-26 14:58:13,920    1032     INFO result.py(91) - 耗时： 0.12369275093078613
2021-08-26 14:58:13,920   17744     INFO test_runner.py(193) - 
Pass	test_applyClient用户资料提交 (Test_Case.test_运营用户创建审批.Test_新建用户)

2021-08-26 14:58:13,920   17744    ERROR test_runner.py(195) - 
Fail	test_submitAudit提交审核 (Test_Case.test_运营用户创建审批.Test_新建用户)

2021-08-26 14:58:13,921   17744     INFO test_runner.py(213) - 
测试结束！
运行时间: 0:00:00.853141
共计执行用例数量：2
执行成功用例数量：1
执行失败用例数量：1
跳过执行用例数量：0
产生异常用例数量：0

2021-08-26 14:59:29,789   15412     INFO test_runner.py(156) - 预计并发线程数：1
2021-08-26 14:59:29,791   10904     INFO result.py(69) - 开始测试： test_applyClient用户资料提交 (Test_Case.test_运营用户创建审批.Test_新建用户)
2021-08-26 14:59:29,792   10904     INFO test_运营用户创建审批.py(23) - 初始化 Session
2021-08-26 14:59:30,231   10904     INFO test_运营用户创建审批.py(18) - 关闭 Session
2021-08-26 14:59:30,246   10904     INFO result.py(156) - 测试执行通过： test_applyClient用户资料提交 (Test_Case.test_运营用户创建审批.Test_新建用户)
2021-08-26 14:59:30,246   10904     INFO result.py(90) - 测试结束： test_applyClient用户资料提交 (Test_Case.test_运营用户创建审批.Test_新建用户)
2021-08-26 14:59:30,261   10904     INFO result.py(91) - 耗时： 0.45381712913513184
2021-08-26 14:59:30,261   10904     INFO result.py(69) - 开始测试： test_submitAudit提交审核 (Test_Case.test_运营用户创建审批.Test_新建用户)
2021-08-26 14:59:30,261   10904     INFO test_运营用户创建审批.py(197) - 初始化 Session
2021-08-26 14:59:30,386   10904     INFO test_运营用户创建审批.py(18) - 关闭 Session
2021-08-26 14:59:30,386   10904  WARNING result.py(190) - 测试未通过： test_submitAudit提交审核 (Test_Case.test_运营用户创建审批.Test_新建用户)
Traceback (most recent call last):
  File "F:\python\EDDID_CDMS\Test_Case\test_运营用户创建审批.py", line 223, in test_submitAudit提交审核
    self.assertEqual("操作成功", r.json().get("msg"))
AssertionError: '操作成功' != '错误码:[MAS_01103],客户信息为空。'
- 操作成功
+ 错误码:[MAS_01103],客户信息为空。


2021-08-26 14:59:30,386   10904     INFO result.py(90) - 测试结束： test_submitAudit提交审核 (Test_Case.test_运营用户创建审批.Test_新建用户)
2021-08-26 14:59:30,386   10904     INFO result.py(91) - 耗时： 0.12458038330078125
2021-08-26 14:59:30,387   15412     INFO test_runner.py(193) - 
Pass	test_applyClient用户资料提交 (Test_Case.test_运营用户创建审批.Test_新建用户)

2021-08-26 14:59:30,387   15412    ERROR test_runner.py(195) - 
Fail	test_submitAudit提交审核 (Test_Case.test_运营用户创建审批.Test_新建用户)

2021-08-26 14:59:30,388   15412     INFO test_runner.py(213) - 
测试结束！
运行时间: 0:00:00.801504
共计执行用例数量：2
执行成功用例数量：1
执行失败用例数量：1
跳过执行用例数量：0
产生异常用例数量：0

2021-08-26 15:01:36,654   11368     INFO test_runner.py(156) - 预计并发线程数：1
2021-08-26 15:01:36,655    3060     INFO result.py(69) - 开始测试： test_applyClient用户资料提交 (Test_Case.test_运营用户创建审批.Test_新建用户)
2021-08-26 15:01:36,655    3060     INFO test_运营用户创建审批.py(23) - 初始化 Session
2021-08-26 15:01:37,166    3060     INFO test_运营用户创建审批.py(18) - 关闭 Session
2021-08-26 15:01:37,166    3060     INFO result.py(156) - 测试执行通过： test_applyClient用户资料提交 (Test_Case.test_运营用户创建审批.Test_新建用户)
2021-08-26 15:01:37,182    3060     INFO result.py(90) - 测试结束： test_applyClient用户资料提交 (Test_Case.test_运营用户创建审批.Test_新建用户)
2021-08-26 15:01:37,198    3060     INFO result.py(91) - 耗时： 0.5268902778625488
2021-08-26 15:01:37,198    3060     INFO result.py(69) - 开始测试： test_submitAudit提交审核 (Test_Case.test_运营用户创建审批.Test_新建用户)
2021-08-26 15:01:37,198    3060     INFO test_运营用户创建审批.py(197) - 初始化 Session
2021-08-26 15:01:37,271    3060     INFO test_运营用户创建审批.py(210) - applyId的植为'1147393'
2021-08-26 15:01:37,299    3060     INFO test_运营用户创建审批.py(18) - 关闭 Session
2021-08-26 15:01:37,300    3060  WARNING result.py(190) - 测试未通过： test_submitAudit提交审核 (Test_Case.test_运营用户创建审批.Test_新建用户)
Traceback (most recent call last):
  File "F:\python\EDDID_CDMS\Test_Case\test_运营用户创建审批.py", line 224, in test_submitAudit提交审核
    self.assertEqual("操作成功", r.json().get("msg"))
AssertionError: '操作成功' != '错误码:[MAS_01103],客户信息为空。'
- 操作成功
+ 错误码:[MAS_01103],客户信息为空。


2021-08-26 15:01:37,300    3060     INFO result.py(90) - 测试结束： test_submitAudit提交审核 (Test_Case.test_运营用户创建审批.Test_新建用户)
2021-08-26 15:01:37,300    3060     INFO result.py(91) - 耗时： 0.10209989547729492
2021-08-26 15:01:37,300   11368     INFO test_runner.py(193) - 
Pass	test_applyClient用户资料提交 (Test_Case.test_运营用户创建审批.Test_新建用户)

2021-08-26 15:01:37,300   11368    ERROR test_runner.py(195) - 
Fail	test_submitAudit提交审核 (Test_Case.test_运营用户创建审批.Test_新建用户)

2021-08-26 15:01:37,301   11368     INFO test_runner.py(213) - 
测试结束！
运行时间: 0:00:00.849912
共计执行用例数量：2
执行成功用例数量：1
执行失败用例数量：1
跳过执行用例数量：0
产生异常用例数量：0

2021-08-26 18:43:19,323   18164     INFO test_runner.py(156) - 预计并发线程数：1
2021-08-26 18:43:19,324   17532     INFO result.py(69) - 开始测试： test_applyClient用户资料提交 (Test_Case.test_运营用户创建审批.Test_新建用户)
2021-08-26 18:43:19,378   17532     INFO test_运营用户创建审批.py(30) - 初始化 Session
2021-08-26 18:43:24,861   17532     INFO test_运营用户创建审批.py(24) - 关闭 Session
2021-08-26 18:43:24,861   17532     INFO result.py(156) - 测试执行通过： test_applyClient用户资料提交 (Test_Case.test_运营用户创建审批.Test_新建用户)
2021-08-26 18:43:24,877   17532     INFO result.py(90) - 测试结束： test_applyClient用户资料提交 (Test_Case.test_运营用户创建审批.Test_新建用户)
2021-08-26 18:43:24,877   17532     INFO result.py(91) - 耗时： 5.553205966949463
2021-08-26 18:43:24,892   17532     INFO result.py(69) - 开始测试： test_submitAudit提交审核 (Test_Case.test_运营用户创建审批.Test_新建用户)
2021-08-26 18:43:24,892   17532     INFO test_运营用户创建审批.py(207) - 获取手机号
2021-08-26 18:43:24,892   17532     INFO test_运营用户创建审批.py(24) - 关闭 Session
2021-08-26 18:43:24,893   17532    ERROR result.py(175) - 测试产生错误： test_submitAudit提交审核 (Test_Case.test_运营用户创建审批.Test_新建用户)
Traceback (most recent call last):
  File "F:\python\EDDID_CDMS\Test_Case\test_运营用户创建审批.py", line 208, in test_submitAudit提交审核
    cd_clnt_apply_info(phone)
  File "F:\python\EDDID_CDMS\Common\eddid_data_update.py", line 8, in cd_clnt_apply_info
    sql="update cd_clnt_wc_match set resolution_status='FALSE'  where wc_case_id IN(select id from cd_clnt_wc_case where check_id in(select id from  cd_clnt_check_info where apply_id in (select apply_id from cd_clnt_apply_basisinfo where apply_no in (SELECT apply_no applyno FROM cd_clnt_apply_basisinfo WHERE apply_id =(select apply_id from cd_clnt_apply_info where phone_no='{phone}')))))".format(
KeyError: 'phone'

2021-08-26 18:43:24,893   17532     INFO result.py(90) - 测试结束： test_submitAudit提交审核 (Test_Case.test_运营用户创建审批.Test_新建用户)
2021-08-26 18:43:24,893   17532     INFO result.py(91) - 耗时： 0.0009686946868896484
2021-08-26 18:43:24,893   18164     INFO test_runner.py(193) - 
Pass	test_applyClient用户资料提交 (Test_Case.test_运营用户创建审批.Test_新建用户)

2021-08-26 18:43:24,893   18164    ERROR test_runner.py(195) - 
Error	test_submitAudit提交审核 (Test_Case.test_运营用户创建审批.Test_新建用户)

2021-08-26 18:43:24,894   18164     INFO test_runner.py(213) - 
测试结束！
运行时间: 0:00:05.776164
共计执行用例数量：2
执行成功用例数量：1
执行失败用例数量：0
跳过执行用例数量：0
产生异常用例数量：1

2021-08-26 18:44:11,210   18368     INFO test_runner.py(156) - 预计并发线程数：1
2021-08-26 18:44:11,211    5524     INFO result.py(69) - 开始测试： test_applyClient用户资料提交 (Test_Case.test_运营用户创建审批.Test_新建用户)
2021-08-26 18:44:11,212    5524     INFO test_运营用户创建审批.py(30) - 初始化 Session
2021-08-26 18:44:16,720    5524     INFO test_运营用户创建审批.py(24) - 关闭 Session
2021-08-26 18:44:16,720    5524     INFO result.py(156) - 测试执行通过： test_applyClient用户资料提交 (Test_Case.test_运营用户创建审批.Test_新建用户)
2021-08-26 18:44:16,720    5524     INFO result.py(90) - 测试结束： test_applyClient用户资料提交 (Test_Case.test_运营用户创建审批.Test_新建用户)
2021-08-26 18:44:16,720    5524     INFO result.py(91) - 耗时： 5.508285999298096
2021-08-26 18:44:16,735    5524     INFO result.py(69) - 开始测试： test_submitAudit提交审核 (Test_Case.test_运营用户创建审批.Test_新建用户)
2021-08-26 18:44:16,735    5524     INFO test_运营用户创建审批.py(207) - 获取手机号
2021-08-26 18:44:16,882    5524     INFO test_运营用户创建审批.py(209) - 已完成修改WorldCheck的状态为FALSE
2021-08-26 18:44:21,094    5524     INFO test_运营用户创建审批.py(24) - 关闭 Session
2021-08-26 18:44:21,094    5524    ERROR result.py(175) - 测试产生错误： test_submitAudit提交审核 (Test_Case.test_运营用户创建审批.Test_新建用户)
Traceback (most recent call last):
  File "F:\python\EDDID_CDMS\Test_Case\test_运营用户创建审批.py", line 220, in test_submitAudit提交审核
    applyId = cd_clnt_apply_info(phone)[0][0]
TypeError: 'NoneType' object is not subscriptable

2021-08-26 18:44:21,094    5524     INFO result.py(90) - 测试结束： test_submitAudit提交审核 (Test_Case.test_运营用户创建审批.Test_新建用户)
2021-08-26 18:44:21,094    5524     INFO result.py(91) - 耗时： 4.358972787857056
2021-08-26 18:44:21,094   18368     INFO test_runner.py(193) - 
Pass	test_applyClient用户资料提交 (Test_Case.test_运营用户创建审批.Test_新建用户)

2021-08-26 18:44:21,094   18368    ERROR test_runner.py(195) - 
Error	test_submitAudit提交审核 (Test_Case.test_运营用户创建审批.Test_新建用户)

2021-08-26 18:44:21,095   18368     INFO test_runner.py(213) - 
测试结束！
运行时间: 0:00:10.098091
共计执行用例数量：2
执行成功用例数量：1
执行失败用例数量：0
跳过执行用例数量：0
产生异常用例数量：1

2021-08-26 18:46:08,644    9104     INFO test_runner.py(156) - 预计并发线程数：1
2021-08-26 18:46:08,645   18540     INFO result.py(69) - 开始测试： test_applyClient用户资料提交 (Test_Case.test_运营用户创建审批.Test_新建用户)
2021-08-26 18:46:08,668   18540     INFO test_运营用户创建审批.py(30) - 初始化 Session
2021-08-26 18:46:14,119   18540     INFO test_运营用户创建审批.py(24) - 关闭 Session
2021-08-26 18:46:14,134   18540     INFO result.py(156) - 测试执行通过： test_applyClient用户资料提交 (Test_Case.test_运营用户创建审批.Test_新建用户)
2021-08-26 18:46:14,134   18540     INFO result.py(90) - 测试结束： test_applyClient用户资料提交 (Test_Case.test_运营用户创建审批.Test_新建用户)
2021-08-26 18:46:14,149   18540     INFO result.py(91) - 耗时： 5.4873127937316895
2021-08-26 18:46:14,165   18540     INFO result.py(69) - 开始测试： test_submitAudit提交审核 (Test_Case.test_运营用户创建审批.Test_新建用户)
2021-08-26 18:46:14,165   18540     INFO test_运营用户创建审批.py(207) - 获取手机号
2021-08-26 18:46:14,314   18540     INFO test_运营用户创建审批.py(209) - 已完成修改WorldCheck的状态为FALSE
2021-08-26 18:46:18,510   18540     INFO test_运营用户创建审批.py(24) - 关闭 Session
2021-08-26 18:46:18,511   18540    ERROR result.py(175) - 测试产生错误： test_submitAudit提交审核 (Test_Case.test_运营用户创建审批.Test_新建用户)
Traceback (most recent call last):
  File "F:\python\EDDID_CDMS\Test_Case\test_运营用户创建审批.py", line 220, in test_submitAudit提交审核
    applyId = cd_clnt_apply_info(phone)[0][0]
TypeError: 'NoneType' object is not subscriptable

2021-08-26 18:46:18,511   18540     INFO result.py(90) - 测试结束： test_submitAudit提交审核 (Test_Case.test_运营用户创建审批.Test_新建用户)
2021-08-26 18:46:18,511   18540     INFO result.py(91) - 耗时： 4.3453991413116455
2021-08-26 18:46:18,511    9104     INFO test_runner.py(193) - 
Pass	test_applyClient用户资料提交 (Test_Case.test_运营用户创建审批.Test_新建用户)

2021-08-26 18:46:18,511    9104    ERROR test_runner.py(195) - 
Error	test_submitAudit提交审核 (Test_Case.test_运营用户创建审批.Test_新建用户)

2021-08-26 18:46:18,512    9104     INFO test_runner.py(213) - 
测试结束！
运行时间: 0:00:10.069962
共计执行用例数量：2
执行成功用例数量：1
执行失败用例数量：0
跳过执行用例数量：0
产生异常用例数量：1

2021-08-26 18:53:55,948   20008     INFO test_runner.py(156) - 预计并发线程数：1
2021-08-26 18:53:55,950   24984     INFO result.py(69) - 开始测试： test_applyClient用户资料提交 (Test_Case.test_运营用户创建审批.Test_新建用户)
2021-08-26 18:53:56,012   24984     INFO test_运营用户创建审批.py(30) - 初始化 Session
2021-08-26 18:54:01,464   24984     INFO test_运营用户创建审批.py(24) - 关闭 Session
2021-08-26 18:54:01,479   24984     INFO result.py(156) - 测试执行通过： test_applyClient用户资料提交 (Test_Case.test_运营用户创建审批.Test_新建用户)
2021-08-26 18:54:01,479   24984     INFO result.py(90) - 测试结束： test_applyClient用户资料提交 (Test_Case.test_运营用户创建审批.Test_新建用户)
2021-08-26 18:54:01,479   24984     INFO result.py(91) - 耗时： 5.529270172119141
2021-08-26 18:54:01,494   24984     INFO result.py(69) - 开始测试： test_submitAudit提交审核 (Test_Case.test_运营用户创建审批.Test_新建用户)
2021-08-26 18:54:01,659   24984     INFO test_运营用户创建审批.py(209) - 已完成修改WorldCheck的状态为FALSE
2021-08-26 18:54:05,740   24984     INFO test_运营用户创建审批.py(220) - 提交审核获取到的手机号为：11808569618
2021-08-26 18:54:05,874   24984     INFO test_运营用户创建审批.py(223) - applyId的值为：None
2021-08-26 18:54:05,907   24984     INFO test_运营用户创建审批.py(24) - 关闭 Session
2021-08-26 18:54:05,908   24984  WARNING result.py(190) - 测试未通过： test_submitAudit提交审核 (Test_Case.test_运营用户创建审批.Test_新建用户)
Traceback (most recent call last):
  File "F:\python\EDDID_CDMS\Test_Case\test_运营用户创建审批.py", line 235, in test_submitAudit提交审核
    self.assertEqual("操作成功", r.json().get("msg"))
AssertionError: '操作成功' != '错误码:[MAS_01103],客户信息为空。'
- 操作成功
+ 错误码:[MAS_01103],客户信息为空。


2021-08-26 18:54:05,908   24984     INFO result.py(90) - 测试结束： test_submitAudit提交审核 (Test_Case.test_运营用户创建审批.Test_新建用户)
2021-08-26 18:54:05,908   24984     INFO result.py(91) - 耗时： 4.413370847702026
2021-08-26 18:54:05,908   20008     INFO test_runner.py(193) - 
Pass	test_applyClient用户资料提交 (Test_Case.test_运营用户创建审批.Test_新建用户)

2021-08-26 18:54:05,908   20008    ERROR test_runner.py(195) - 
Fail	test_submitAudit提交审核 (Test_Case.test_运营用户创建审批.Test_新建用户)

2021-08-26 18:54:05,909   20008     INFO test_runner.py(213) - 
测试结束！
运行时间: 0:00:10.222977
共计执行用例数量：2
执行成功用例数量：1
执行失败用例数量：1
跳过执行用例数量：0
产生异常用例数量：0

2021-08-26 19:00:39,506   19872     INFO test_runner.py(156) - 预计并发线程数：1
2021-08-26 19:00:39,508   13204     INFO result.py(69) - 开始测试： test_applyClient用户资料提交 (Test_Case.test_运营用户创建审批.Test_新建用户)
2021-08-26 19:00:39,570   13204     INFO test_运营用户创建审批.py(32) - 初始化 Session
2021-08-26 19:00:39,725   13204     INFO test_运营用户创建审批.py(41) - 接口请求url为：
2021-08-26 19:00:44,983   13204     INFO test_运营用户创建审批.py(25) - 关闭 Session
2021-08-26 19:00:44,983   13204     INFO result.py(156) - 测试执行通过： test_applyClient用户资料提交 (Test_Case.test_运营用户创建审批.Test_新建用户)
2021-08-26 19:00:44,998   13204     INFO result.py(90) - 测试结束： test_applyClient用户资料提交 (Test_Case.test_运营用户创建审批.Test_新建用户)
2021-08-26 19:00:44,998   13204     INFO result.py(91) - 耗时： 5.490333795547485
2021-08-26 19:00:45,014   13204     INFO result.py(69) - 开始测试： test_submitAudit提交审核 (Test_Case.test_运营用户创建审批.Test_新建用户)
2021-08-26 19:00:45,193   13204     INFO test_运营用户创建审批.py(213) - 已完成修改WorldCheck的状态为FALSE
2021-08-26 19:00:49,229   13204     INFO test_运营用户创建审批.py(223) - 接口请求url为：
2021-08-26 19:00:49,229   13204     INFO test_运营用户创建审批.py(225) - 提交审核获取到的手机号为：10889536996
2021-08-26 19:00:49,363   13204     INFO test_运营用户创建审批.py(228) - 请求数据库cd_clnt_apply_info查询到applyId的值为：None
2021-08-26 19:00:49,429   13204     INFO test_运营用户创建审批.py(25) - 关闭 Session
2021-08-26 19:00:49,430   13204  WARNING result.py(190) - 测试未通过： test_submitAudit提交审核 (Test_Case.test_运营用户创建审批.Test_新建用户)
Traceback (most recent call last):
  File "F:\python\EDDID_CDMS\Test_Case\test_运营用户创建审批.py", line 240, in test_submitAudit提交审核
    self.assertEqual("操作成功", r.json().get("msg"))
AssertionError: '操作成功' != '错误码：[CDMS_04008]，申请单编号为空。'
- 操作成功
+ 错误码：[CDMS_04008]，申请单编号为空。


2021-08-26 19:00:49,430   13204     INFO result.py(90) - 测试结束： test_submitAudit提交审核 (Test_Case.test_运营用户创建审批.Test_新建用户)
2021-08-26 19:00:49,430   13204     INFO result.py(91) - 耗时： 4.415864944458008
2021-08-26 19:00:49,430   19872     INFO test_runner.py(193) - 
Pass	test_applyClient用户资料提交 (Test_Case.test_运营用户创建审批.Test_新建用户)

2021-08-26 19:00:49,430   19872    ERROR test_runner.py(195) - 
Fail	test_submitAudit提交审核 (Test_Case.test_运营用户创建审批.Test_新建用户)

2021-08-26 19:00:49,431   19872     INFO test_runner.py(213) - 
测试结束！
运行时间: 0:00:10.201155
共计执行用例数量：2
执行成功用例数量：1
执行失败用例数量：1
跳过执行用例数量：0
产生异常用例数量：0

2021-08-26 19:05:27,026   21156     INFO test_runner.py(156) - 预计并发线程数：1
2021-08-26 19:05:27,028   25660     INFO result.py(69) - 开始测试： test_applyClient用户资料提交 (Test_Case.test_运营用户创建审批.Test_新建用户)
2021-08-26 19:05:27,029   25660     INFO test_运营用户创建审批.py(32) - 初始化 Session
2021-08-26 19:05:27,258   25660     INFO test_运营用户创建审批.py(41) - 接口请求url为：
2021-08-26 19:05:32,518   25660     INFO test_运营用户创建审批.py(25) - 关闭 Session
2021-08-26 19:05:32,549   25660     INFO result.py(156) - 测试执行通过： test_applyClient用户资料提交 (Test_Case.test_运营用户创建审批.Test_新建用户)
2021-08-26 19:05:32,549   25660     INFO result.py(90) - 测试结束： test_applyClient用户资料提交 (Test_Case.test_运营用户创建审批.Test_新建用户)
2021-08-26 19:05:32,549   25660     INFO result.py(91) - 耗时： 5.520256757736206
2021-08-26 19:05:32,565   25660     INFO result.py(69) - 开始测试： test_submitAudit提交审核 (Test_Case.test_运营用户创建审批.Test_新建用户)
2021-08-26 19:05:32,715   25660     INFO test_运营用户创建审批.py(213) - 已完成修改WorldCheck的状态为FALSE
2021-08-26 19:05:36,806   25660     INFO test_运营用户创建审批.py(223) - 接口请求url为：
2021-08-26 19:05:36,807   25660     INFO test_运营用户创建审批.py(225) - 提交审核获取到的手机号为：10209090034
2021-08-26 19:05:36,949   25660     INFO test_运营用户创建审批.py(228) - 请求数据库cd_clnt_apply_info查询到applyId的值为：None
2021-08-26 19:05:36,979   25660     INFO test_运营用户创建审批.py(25) - 关闭 Session
2021-08-26 19:05:36,980   25660  WARNING result.py(190) - 测试未通过： test_submitAudit提交审核 (Test_Case.test_运营用户创建审批.Test_新建用户)
Traceback (most recent call last):
  File "F:\python\EDDID_CDMS\Test_Case\test_运营用户创建审批.py", line 240, in test_submitAudit提交审核
    self.assertEqual("操作成功", r.json().get("msg"))
AssertionError: '操作成功' != '错误码：[CDMS_04008]，申请单编号为空。'
- 操作成功
+ 错误码：[CDMS_04008]，申请单编号为空。


2021-08-26 19:05:36,980   25660     INFO result.py(90) - 测试结束： test_submitAudit提交审核 (Test_Case.test_运营用户创建审批.Test_新建用户)
2021-08-26 19:05:36,980   25660     INFO result.py(91) - 耗时： 4.415088176727295
2021-08-26 19:05:36,980   21156     INFO test_runner.py(193) - 
Pass	test_applyClient用户资料提交 (Test_Case.test_运营用户创建审批.Test_新建用户)

2021-08-26 19:05:36,980   21156    ERROR test_runner.py(195) - 
Fail	test_submitAudit提交审核 (Test_Case.test_运营用户创建审批.Test_新建用户)

2021-08-26 19:05:36,981   21156     INFO test_runner.py(213) - 
测试结束！
运行时间: 0:00:10.150191
共计执行用例数量：2
执行成功用例数量：1
执行失败用例数量：1
跳过执行用例数量：0
产生异常用例数量：0

2021-08-26 19:07:54,089   15632     INFO test_runner.py(156) - 预计并发线程数：1
2021-08-26 19:07:54,090   20676     INFO result.py(69) - 开始测试： test_applyClient用户资料提交 (Test_Case.test_运营用户创建审批.Test_新建用户)
2021-08-26 19:07:54,090   20676     INFO test_运营用户创建审批.py(32) - 初始化 Session
2021-08-26 19:07:54,297   20676     INFO test_运营用户创建审批.py(41) - 接口请求url为：
2021-08-26 19:07:59,567   20676     INFO test_运营用户创建审批.py(25) - 关闭 Session
2021-08-26 19:07:59,567   20676     INFO result.py(156) - 测试执行通过： test_applyClient用户资料提交 (Test_Case.test_运营用户创建审批.Test_新建用户)
2021-08-26 19:07:59,567   20676     INFO result.py(90) - 测试结束： test_applyClient用户资料提交 (Test_Case.test_运营用户创建审批.Test_新建用户)
2021-08-26 19:07:59,567   20676     INFO result.py(91) - 耗时： 5.476747989654541
2021-08-26 19:07:59,567   20676     INFO result.py(69) - 开始测试： test_submitAudit提交审核 (Test_Case.test_运营用户创建审批.Test_新建用户)
2021-08-26 19:07:59,712   20676     INFO test_运营用户创建审批.py(213) - 已完成修改WorldCheck的状态为FALSE
2021-08-26 19:08:03,752   20676     INFO test_运营用户创建审批.py(223) - 接口请求url为：
2021-08-26 19:08:03,752   20676     INFO test_运营用户创建审批.py(225) - 提交审核获取到的手机号为：19898077267
2021-08-26 19:08:03,825   20676     INFO test_运营用户创建审批.py(25) - 关闭 Session
2021-08-26 19:08:03,825   20676    ERROR result.py(175) - 测试产生错误： test_submitAudit提交审核 (Test_Case.test_运营用户创建审批.Test_新建用户)
Traceback (most recent call last):
  File "F:\python\EDDID_CDMS\Test_Case\test_运营用户创建审批.py", line 226, in test_submitAudit提交审核
    applyId = cd_clnt_apply_info(phone)
  File "F:\python\EDDID_CDMS\Common\eddid_data_select.py", line 9, in cd_clnt_apply_info
    applyid=apply_id[0][0]
IndexError: tuple index out of range

2021-08-26 19:08:03,826   20676     INFO result.py(90) - 测试结束： test_submitAudit提交审核 (Test_Case.test_运营用户创建审批.Test_新建用户)
2021-08-26 19:08:03,826   20676     INFO result.py(91) - 耗时： 4.258055210113525
2021-08-26 19:08:03,826   15632     INFO test_runner.py(193) - 
Pass	test_applyClient用户资料提交 (Test_Case.test_运营用户创建审批.Test_新建用户)

2021-08-26 19:08:03,826   15632    ERROR test_runner.py(195) - 
Error	test_submitAudit提交审核 (Test_Case.test_运营用户创建审批.Test_新建用户)

2021-08-26 19:08:03,827   15632     INFO test_runner.py(213) - 
测试结束！
运行时间: 0:00:09.935320
共计执行用例数量：2
执行成功用例数量：1
执行失败用例数量：0
跳过执行用例数量：0
产生异常用例数量：1

2021-08-26 19:13:15,391   26276     INFO test_runner.py(156) - 预计并发线程数：1
2021-08-26 19:13:15,393    8064     INFO result.py(69) - 开始测试： test_applyClient用户资料提交 (Test_Case.test_运营用户创建审批.Test_新建用户)
2021-08-26 19:13:15,393    8064     INFO test_运营用户创建审批.py(32) - 初始化 Session
2021-08-26 19:13:15,600    8064     INFO test_运营用户创建审批.py(41) - 接口请求url为：
2021-08-26 19:13:20,919    8064     INFO test_运营用户创建审批.py(25) - 关闭 Session
2021-08-26 19:13:20,919    8064     INFO result.py(156) - 测试执行通过： test_applyClient用户资料提交 (Test_Case.test_运营用户创建审批.Test_新建用户)
2021-08-26 19:13:20,919    8064     INFO result.py(90) - 测试结束： test_applyClient用户资料提交 (Test_Case.test_运营用户创建审批.Test_新建用户)
2021-08-26 19:13:20,934    8064     INFO result.py(91) - 耗时： 5.525180816650391
2021-08-26 19:13:20,934    8064     INFO result.py(69) - 开始测试： test_submitAudit提交审核 (Test_Case.test_运营用户创建审批.Test_新建用户)
2021-08-26 19:13:21,111    8064     INFO test_运营用户创建审批.py(213) - 已完成修改WorldCheck的状态为FALSE
2021-08-26 19:13:25,149    8064     INFO test_运营用户创建审批.py(223) - 接口请求url为：
2021-08-26 19:13:25,150    8064     INFO test_运营用户创建审批.py(225) - 提交审核获取到的手机号为：16230228812
2021-08-26 19:13:25,213    8064     INFO test_运营用户创建审批.py(25) - 关闭 Session
2021-08-26 19:13:25,213    8064    ERROR result.py(175) - 测试产生错误： test_submitAudit提交审核 (Test_Case.test_运营用户创建审批.Test_新建用户)
Traceback (most recent call last):
  File "F:\python\EDDID_CDMS\Test_Case\test_运营用户创建审批.py", line 226, in test_submitAudit提交审核
    applyId = cd_clnt_apply_info(phone)
  File "F:\python\EDDID_CDMS\Common\eddid_data_select.py", line 6, in cd_clnt_apply_info
    apply_id = SQL_Check.eddid_gfss_sit(database="eddid_gfss_sit",
IndexError: tuple index out of range

2021-08-26 19:13:25,214    8064     INFO result.py(90) - 测试结束： test_submitAudit提交审核 (Test_Case.test_运营用户创建审批.Test_新建用户)
2021-08-26 19:13:25,214    8064     INFO result.py(91) - 耗时： 4.280611991882324
2021-08-26 19:13:25,214   26276     INFO test_runner.py(193) - 
Pass	test_applyClient用户资料提交 (Test_Case.test_运营用户创建审批.Test_新建用户)

2021-08-26 19:13:25,214   26276    ERROR test_runner.py(195) - 
Error	test_submitAudit提交审核 (Test_Case.test_运营用户创建审批.Test_新建用户)

2021-08-26 19:13:25,215   26276     INFO test_runner.py(213) - 
测试结束！
运行时间: 0:00:10.014039
共计执行用例数量：2
执行成功用例数量：1
执行失败用例数量：0
跳过执行用例数量：0
产生异常用例数量：1

2021-08-26 19:15:56,900   22512     INFO test_runner.py(156) - 预计并发线程数：1
2021-08-26 19:15:56,902   25080     INFO result.py(69) - 开始测试： test_applyClient用户资料提交 (Test_Case.test_运营用户创建审批.Test_新建用户)
2021-08-26 19:15:56,903   25080     INFO test_运营用户创建审批.py(32) - 初始化 Session
2021-08-26 19:15:57,069   25080     INFO test_运营用户创建审批.py(41) - 接口请求url为：
2021-08-26 19:16:02,350   25080     INFO test_运营用户创建审批.py(25) - 关闭 Session
2021-08-26 19:16:02,366   25080     INFO result.py(156) - 测试执行通过： test_applyClient用户资料提交 (Test_Case.test_运营用户创建审批.Test_新建用户)
2021-08-26 19:16:02,381   25080     INFO result.py(90) - 测试结束： test_applyClient用户资料提交 (Test_Case.test_运营用户创建审批.Test_新建用户)
2021-08-26 19:16:02,397   25080     INFO result.py(91) - 耗时： 5.478368759155273
2021-08-26 19:16:02,414   25080     INFO result.py(69) - 开始测试： test_submitAudit提交审核 (Test_Case.test_运营用户创建审批.Test_新建用户)
2021-08-26 19:16:02,559   25080     INFO test_运营用户创建审批.py(213) - 已完成修改WorldCheck的状态为FALSE
2021-08-26 19:16:06,590   25080     INFO test_运营用户创建审批.py(223) - 接口请求url为：
2021-08-26 19:16:06,590   25080     INFO test_运营用户创建审批.py(225) - 提交审核获取到的手机号为：10959500602
2021-08-26 19:16:06,654   25080     INFO test_运营用户创建审批.py(228) - 请求数据库cd_clnt_apply_info查询到applyId的值为：()
2021-08-26 19:16:06,689   25080     INFO test_运营用户创建审批.py(25) - 关闭 Session
2021-08-26 19:16:06,690   25080  WARNING result.py(190) - 测试未通过： test_submitAudit提交审核 (Test_Case.test_运营用户创建审批.Test_新建用户)
Traceback (most recent call last):
  File "F:\python\EDDID_CDMS\Test_Case\test_运营用户创建审批.py", line 240, in test_submitAudit提交审核
    self.assertEqual("操作成功", r.json().get("msg"))
AssertionError: '操作成功' != 'JSON invalid format'
- 操作成功
+ JSON invalid format


2021-08-26 19:16:06,690   25080     INFO result.py(90) - 测试结束： test_submitAudit提交审核 (Test_Case.test_运营用户创建审批.Test_新建用户)
2021-08-26 19:16:06,690   25080     INFO result.py(91) - 耗时： 4.276490211486816
2021-08-26 19:16:06,690   22512     INFO test_runner.py(193) - 
Pass	test_applyClient用户资料提交 (Test_Case.test_运营用户创建审批.Test_新建用户)

2021-08-26 19:16:06,690   22512    ERROR test_runner.py(195) - 
Fail	test_submitAudit提交审核 (Test_Case.test_运营用户创建审批.Test_新建用户)

2021-08-26 19:16:06,691   22512     INFO test_runner.py(213) - 
测试结束！
运行时间: 0:00:09.994231
共计执行用例数量：2
执行成功用例数量：1
执行失败用例数量：1
跳过执行用例数量：0
产生异常用例数量：0

2021-08-26 19:19:48,590    9132     INFO test_runner.py(156) - 预计并发线程数：1
2021-08-26 19:19:48,592   11380     INFO result.py(69) - 开始测试： test_applyClient用户资料提交 (Test_Case.test_运营用户创建审批.Test_新建用户)
2021-08-26 19:19:48,593   11380     INFO test_运营用户创建审批.py(32) - 初始化 Session
2021-08-26 19:19:48,818   11380     INFO test_运营用户创建审批.py(42) - 接口请求url为：
2021-08-26 19:19:54,098   11380     INFO test_运营用户创建审批.py(25) - 关闭 Session
2021-08-26 19:19:54,113   11380     INFO result.py(156) - 测试执行通过： test_applyClient用户资料提交 (Test_Case.test_运营用户创建审批.Test_新建用户)
2021-08-26 19:19:54,113   11380     INFO result.py(90) - 测试结束： test_applyClient用户资料提交 (Test_Case.test_运营用户创建审批.Test_新建用户)
2021-08-26 19:19:54,129   11380     INFO result.py(91) - 耗时： 5.521281719207764
2021-08-26 19:19:54,145   11380     INFO result.py(69) - 开始测试： test_submitAudit提交审核 (Test_Case.test_运营用户创建审批.Test_新建用户)
2021-08-26 19:19:54,324   11380     INFO test_运营用户创建审批.py(214) - 已完成修改WorldCheck的状态为FALSE
2021-08-26 19:19:58,366   11380     INFO test_运营用户创建审批.py(224) - 接口请求url为：
2021-08-26 19:19:58,367   11380     INFO test_运营用户创建审批.py(226) - 提交审核获取到的手机号为：12394306928
2021-08-26 19:19:58,427   11380     INFO test_运营用户创建审批.py(229) - 请求数据库cd_clnt_apply_info查询到applyId的值为：()
2021-08-26 19:19:58,461   11380     INFO test_运营用户创建审批.py(25) - 关闭 Session
2021-08-26 19:19:58,461   11380  WARNING result.py(190) - 测试未通过： test_submitAudit提交审核 (Test_Case.test_运营用户创建审批.Test_新建用户)
Traceback (most recent call last):
  File "F:\python\EDDID_CDMS\Test_Case\test_运营用户创建审批.py", line 241, in test_submitAudit提交审核
    self.assertEqual("操作成功", r.json().get("msg"))
AssertionError: '操作成功' != 'JSON invalid format'
- 操作成功
+ JSON invalid format


2021-08-26 19:19:58,461   11380     INFO result.py(90) - 测试结束： test_submitAudit提交审核 (Test_Case.test_运营用户创建审批.Test_新建用户)
2021-08-26 19:19:58,462   11380     INFO result.py(91) - 耗时： 4.3161797523498535
2021-08-26 19:19:58,462    9132     INFO test_runner.py(193) - 
Pass	test_applyClient用户资料提交 (Test_Case.test_运营用户创建审批.Test_新建用户)

2021-08-26 19:19:58,462    9132    ERROR test_runner.py(195) - 
Fail	test_submitAudit提交审核 (Test_Case.test_运营用户创建审批.Test_新建用户)

2021-08-26 19:19:58,463    9132     INFO test_runner.py(213) - 
测试结束！
运行时间: 0:00:10.075537
共计执行用例数量：2
执行成功用例数量：1
执行失败用例数量：1
跳过执行用例数量：0
产生异常用例数量：0

2021-08-26 19:21:15,280   18196     INFO test_runner.py(156) - 预计并发线程数：1
2021-08-26 19:21:15,282   14448     INFO result.py(69) - 开始测试： test_applyClient用户资料提交 (Test_Case.test_运营用户创建审批.Test_新建用户)
2021-08-26 19:21:15,301   14448     INFO test_运营用户创建审批.py(32) - 初始化 Session
2021-08-26 19:21:15,518   14448     INFO test_运营用户创建审批.py(42) - 接口请求url为：
2021-08-26 19:21:20,786   14448     INFO test_运营用户创建审批.py(25) - 关闭 Session
2021-08-26 19:21:20,786   14448     INFO result.py(156) - 测试执行通过： test_applyClient用户资料提交 (Test_Case.test_运营用户创建审批.Test_新建用户)
2021-08-26 19:21:20,802   14448     INFO result.py(90) - 测试结束： test_applyClient用户资料提交 (Test_Case.test_运营用户创建审批.Test_新建用户)
2021-08-26 19:21:20,818   14448     INFO result.py(91) - 耗时： 5.501280784606934
2021-08-26 19:21:20,818   14448     INFO result.py(69) - 开始测试： test_submitAudit提交审核 (Test_Case.test_运营用户创建审批.Test_新建用户)
2021-08-26 19:21:20,971   14448     INFO test_运营用户创建审批.py(214) - 已完成修改WorldCheck的状态为FALSE
2021-08-26 19:21:25,036   14448     INFO test_运营用户创建审批.py(227) - 接口请求url为：
2021-08-26 19:21:25,036   14448     INFO test_运营用户创建审批.py(229) - 提交审核获取到的手机号为：19760274508
2021-08-26 19:21:25,099   14448     INFO test_运营用户创建审批.py(232) - 请求数据库cd_clnt_apply_info查询到applyId的值为：()
2021-08-26 19:21:25,131   14448     INFO test_运营用户创建审批.py(25) - 关闭 Session
2021-08-26 19:21:25,132   14448  WARNING result.py(190) - 测试未通过： test_submitAudit提交审核 (Test_Case.test_运营用户创建审批.Test_新建用户)
Traceback (most recent call last):
  File "F:\python\EDDID_CDMS\Test_Case\test_运营用户创建审批.py", line 244, in test_submitAudit提交审核
    self.assertEqual("操作成功", r.json().get("msg"))
AssertionError: '操作成功' != 'JSON invalid format'
- 操作成功
+ JSON invalid format


2021-08-26 19:21:25,132   14448     INFO result.py(90) - 测试结束： test_submitAudit提交审核 (Test_Case.test_运营用户创建审批.Test_新建用户)
2021-08-26 19:21:25,132   14448     INFO result.py(91) - 耗时： 4.314119577407837
2021-08-26 19:21:25,132   18196     INFO test_runner.py(193) - 
Pass	test_applyClient用户资料提交 (Test_Case.test_运营用户创建审批.Test_新建用户)

2021-08-26 19:21:25,132   18196    ERROR test_runner.py(195) - 
Fail	test_submitAudit提交审核 (Test_Case.test_运营用户创建审批.Test_新建用户)

2021-08-26 19:21:25,133   18196     INFO test_runner.py(213) - 
测试结束！
运行时间: 0:00:10.059543
共计执行用例数量：2
执行成功用例数量：1
执行失败用例数量：1
跳过执行用例数量：0
产生异常用例数量：0

2021-08-26 19:22:53,342    2708     INFO test_runner.py(156) - 预计并发线程数：1
2021-08-26 19:22:53,343   25552     INFO result.py(69) - 开始测试： test_applyClient用户资料提交 (Test_Case.test_运营用户创建审批.Test_新建用户)
2021-08-26 19:22:53,344   25552     INFO test_运营用户创建审批.py(32) - 初始化 Session
2021-08-26 19:22:53,620   25552     INFO test_运营用户创建审批.py(42) - 接口请求url为：
2021-08-26 19:22:58,917   25552     INFO test_运营用户创建审批.py(25) - 关闭 Session
2021-08-26 19:22:58,917   25552     INFO result.py(156) - 测试执行通过： test_applyClient用户资料提交 (Test_Case.test_运营用户创建审批.Test_新建用户)
2021-08-26 19:22:58,917   25552     INFO result.py(90) - 测试结束： test_applyClient用户资料提交 (Test_Case.test_运营用户创建审批.Test_新建用户)
2021-08-26 19:22:58,932   25552     INFO result.py(91) - 耗时： 5.573084115982056
2021-08-26 19:22:58,947   25552     INFO result.py(69) - 开始测试： test_submitAudit提交审核 (Test_Case.test_运营用户创建审批.Test_新建用户)
2021-08-26 19:22:59,093   25552     INFO test_运营用户创建审批.py(214) - 已完成修改WorldCheck的状态为FALSE
2021-08-26 19:23:03,172   25552     INFO test_运营用户创建审批.py(227) - 接口请求url为：
2021-08-26 19:23:03,172   25552     INFO test_运营用户创建审批.py(229) - 提交审核获取到的手机号为：11249468368
2021-08-26 19:23:03,250   25552     INFO test_运营用户创建审批.py(232) - 请求数据库cd_clnt_apply_info查询到applyId的值为：()
2021-08-26 19:23:03,283   25552     INFO test_运营用户创建审批.py(25) - 关闭 Session
2021-08-26 19:23:03,284   25552  WARNING result.py(190) - 测试未通过： test_submitAudit提交审核 (Test_Case.test_运营用户创建审批.Test_新建用户)
Traceback (most recent call last):
  File "F:\python\EDDID_CDMS\Test_Case\test_运营用户创建审批.py", line 244, in test_submitAudit提交审核
    self.assertEqual("操作成功", r.json().get("msg"))
AssertionError: '操作成功' != 'JSON invalid format'
- 操作成功
+ JSON invalid format


2021-08-26 19:23:03,284   25552     INFO result.py(90) - 测试结束： test_submitAudit提交审核 (Test_Case.test_运营用户创建审批.Test_新建用户)
2021-08-26 19:23:03,284   25552     INFO result.py(91) - 耗时： 4.336708307266235
2021-08-26 19:23:03,284    2708     INFO test_runner.py(193) - 
Pass	test_applyClient用户资料提交 (Test_Case.test_运营用户创建审批.Test_新建用户)

2021-08-26 19:23:03,285    2708    ERROR test_runner.py(195) - 
Fail	test_submitAudit提交审核 (Test_Case.test_运营用户创建审批.Test_新建用户)

2021-08-26 19:23:03,285    2708     INFO test_runner.py(213) - 
测试结束！
运行时间: 0:00:10.150800
共计执行用例数量：2
执行成功用例数量：1
执行失败用例数量：1
跳过执行用例数量：0
产生异常用例数量：0

2021-08-26 19:30:05,391    6160     INFO test_runner.py(156) - 预计并发线程数：1
2021-08-26 19:30:05,393    7720     INFO result.py(69) - 开始测试： test_applyClient用户资料提交 (Test_Case.test_运营用户创建审批.Test_新建用户)
2021-08-26 19:30:05,394    7720     INFO test_运营用户创建审批.py(32) - 初始化 Session
2021-08-26 19:30:05,656    7720     INFO test_运营用户创建审批.py(42) - 接口请求url为：
2021-08-26 19:30:10,961    7720     INFO test_运营用户创建审批.py(25) - 关闭 Session
2021-08-26 19:30:10,961    7720     INFO result.py(156) - 测试执行通过： test_applyClient用户资料提交 (Test_Case.test_运营用户创建审批.Test_新建用户)
2021-08-26 19:30:10,961    7720     INFO result.py(90) - 测试结束： test_applyClient用户资料提交 (Test_Case.test_运营用户创建审批.Test_新建用户)
2021-08-26 19:30:10,961    7720     INFO result.py(91) - 耗时： 5.567131519317627
2021-08-26 19:30:10,977    7720     INFO result.py(69) - 开始测试： test_submitAudit提交审核 (Test_Case.test_运营用户创建审批.Test_新建用户)
2021-08-26 19:30:11,155    7720     INFO test_运营用户创建审批.py(215) - 已完成修改WorldCheck的状态为FALSE
2021-08-26 19:30:15,188    7720     INFO test_运营用户创建审批.py(228) - 接口请求url为：
2021-08-26 19:30:15,189    7720     INFO test_运营用户创建审批.py(230) - 提交审核获取到的手机号为：11170251838
2021-08-26 19:30:15,256    7720     INFO test_运营用户创建审批.py(233) - 请求数据库cd_clnt_apply_info查询到applyId的值为：()
2021-08-26 19:30:15,289    7720     INFO test_运营用户创建审批.py(25) - 关闭 Session
2021-08-26 19:30:15,290    7720  WARNING result.py(190) - 测试未通过： test_submitAudit提交审核 (Test_Case.test_运营用户创建审批.Test_新建用户)
Traceback (most recent call last):
  File "F:\python\EDDID_CDMS\Test_Case\test_运营用户创建审批.py", line 246, in test_submitAudit提交审核
    self.assertEqual("操作成功", r.json().get("msg"))
AssertionError: '操作成功' != 'JSON invalid format'
- 操作成功
+ JSON invalid format


2021-08-26 19:30:15,290    7720     INFO result.py(90) - 测试结束： test_submitAudit提交审核 (Test_Case.test_运营用户创建审批.Test_新建用户)
2021-08-26 19:30:15,290    7720     INFO result.py(91) - 耗时： 4.312788009643555
2021-08-26 19:30:15,290    6160     INFO test_runner.py(193) - 
Pass	test_applyClient用户资料提交 (Test_Case.test_运营用户创建审批.Test_新建用户)

2021-08-26 19:30:15,290    6160    ERROR test_runner.py(195) - 
Fail	test_submitAudit提交审核 (Test_Case.test_运营用户创建审批.Test_新建用户)

2021-08-26 19:30:15,291    6160     INFO test_runner.py(213) - 
测试结束！
运行时间: 0:00:10.103935
共计执行用例数量：2
执行成功用例数量：1
执行失败用例数量：1
跳过执行用例数量：0
产生异常用例数量：0

2021-08-27 08:50:02,847   10500     INFO test_runner.py(156) - 预计并发线程数：1
2021-08-27 08:50:02,850   14800     INFO result.py(69) - 开始测试： test_applyClient用户资料提交 (Test_Case.test_运营用户创建审批.Test_新建用户)
2021-08-27 08:50:02,880   14800     INFO test_运营用户创建审批.py(32) - 初始化 Session
2021-08-27 08:50:03,051   14800     INFO test_运营用户创建审批.py(42) - 接口请求url为：
2021-08-27 08:50:08,382   14800     INFO test_运营用户创建审批.py(25) - 关闭 Session
2021-08-27 08:50:08,382   14800     INFO result.py(156) - 测试执行通过： test_applyClient用户资料提交 (Test_Case.test_运营用户创建审批.Test_新建用户)
2021-08-27 08:50:08,398   14800     INFO result.py(90) - 测试结束： test_applyClient用户资料提交 (Test_Case.test_运营用户创建审批.Test_新建用户)
2021-08-27 08:50:08,398   14800     INFO result.py(91) - 耗时： 5.548180341720581
2021-08-27 08:50:08,414   14800     INFO result.py(69) - 开始测试： test_submitAudit提交审核 (Test_Case.test_运营用户创建审批.Test_新建用户)
2021-08-27 08:50:08,596   14800     INFO test_运营用户创建审批.py(215) - 已完成修改WorldCheck的状态为FALSE
2021-08-27 08:50:12,689   14800     INFO test_运营用户创建审批.py(228) - 接口请求url为：
2021-08-27 08:50:12,690   14800     INFO test_运营用户创建审批.py(230) - 提交审核获取到的手机号为：12513509113
2021-08-27 08:50:12,767   14800     INFO test_运营用户创建审批.py(233) - 请求数据库cd_clnt_apply_info查询到applyId的值为：()
2021-08-27 08:50:12,792   14800     INFO test_运营用户创建审批.py(25) - 关闭 Session
2021-08-27 08:50:12,814   14800  WARNING result.py(190) - 测试未通过： test_submitAudit提交审核 (Test_Case.test_运营用户创建审批.Test_新建用户)
Traceback (most recent call last):
  File "F:\python\EDDID_CDMS\Test_Case\test_运营用户创建审批.py", line 246, in test_submitAudit提交审核
    self.assertEqual("操作成功", r.json().get("msg"))
AssertionError: '操作成功' != 'JSON invalid format'
- 操作成功
+ JSON invalid format


2021-08-27 08:50:12,814   14800     INFO result.py(90) - 测试结束： test_submitAudit提交审核 (Test_Case.test_运营用户创建审批.Test_新建用户)
2021-08-27 08:50:12,814   14800     INFO result.py(91) - 耗时： 4.399883270263672
2021-08-27 08:50:12,814   10500     INFO test_runner.py(193) - 
Pass	test_applyClient用户资料提交 (Test_Case.test_运营用户创建审批.Test_新建用户)

2021-08-27 08:50:12,814   10500    ERROR test_runner.py(195) - 
Fail	test_submitAudit提交审核 (Test_Case.test_运营用户创建审批.Test_新建用户)

2021-08-27 08:50:12,815   10500     INFO test_runner.py(213) - 
测试结束！
运行时间: 0:00:10.181411
共计执行用例数量：2
执行成功用例数量：1
执行失败用例数量：1
跳过执行用例数量：0
产生异常用例数量：0

2021-08-27 09:11:32,489    5280     INFO test_runner.py(156) - 预计并发线程数：1
2021-08-27 09:11:32,491   11820     INFO result.py(69) - 开始测试： test_applyClient用户资料提交 (Test_Case.test_运营用户创建审批.Test_新建用户)
2021-08-27 09:11:32,748   11820     INFO test_运营用户创建审批.py(26) - 获取到的token为
2021-08-27 09:11:32,748   11820     INFO test_运营用户创建审批.py(33) - 初始化 Session
2021-08-27 09:11:32,779   11820     INFO test_运营用户创建审批.py(43) - 接口请求url为：
2021-08-27 09:11:38,121   11820     INFO result.py(156) - 测试执行通过： test_applyClient用户资料提交 (Test_Case.test_运营用户创建审批.Test_新建用户)
2021-08-27 09:11:38,121   11820     INFO result.py(90) - 测试结束： test_applyClient用户资料提交 (Test_Case.test_运营用户创建审批.Test_新建用户)
2021-08-27 09:11:38,137   11820     INFO result.py(91) - 耗时： 5.629961013793945
2021-08-27 09:11:38,137   11820     INFO result.py(69) - 开始测试： test_submitAudit提交审核 (Test_Case.test_运营用户创建审批.Test_新建用户)
2021-08-27 09:11:38,163   11820     INFO test_运营用户创建审批.py(26) - 获取到的token为
2021-08-27 09:11:38,300   11820     INFO test_运营用户创建审批.py(216) - 已完成修改WorldCheck的状态为FALSE
2021-08-27 09:11:42,304   11820     INFO test_运营用户创建审批.py(229) - 接口请求url为：
2021-08-27 09:11:42,304   11820     INFO test_运营用户创建审批.py(231) - 提交审核获取到的手机号为：19149946102
2021-08-27 09:11:42,413   11820     INFO test_运营用户创建审批.py(234) - 请求数据库cd_clnt_apply_info查询到applyId的值为：()
2021-08-27 09:11:42,440   11820  WARNING result.py(190) - 测试未通过： test_submitAudit提交审核 (Test_Case.test_运营用户创建审批.Test_新建用户)
Traceback (most recent call last):
  File "F:\python\EDDID_CDMS\Test_Case\test_运营用户创建审批.py", line 247, in test_submitAudit提交审核
    self.assertEqual("操作成功", r.json().get("msg"))
AssertionError: '操作成功' != 'JSON invalid format'
- 操作成功
+ JSON invalid format


2021-08-27 09:11:42,440   11820     INFO result.py(90) - 测试结束： test_submitAudit提交审核 (Test_Case.test_运营用户创建审批.Test_新建用户)
2021-08-27 09:11:42,440   11820     INFO result.py(91) - 耗时： 4.3020713329315186
2021-08-27 09:11:42,441    5280     INFO test_runner.py(193) - 
Pass	test_applyClient用户资料提交 (Test_Case.test_运营用户创建审批.Test_新建用户)

2021-08-27 09:11:42,441    5280    ERROR test_runner.py(195) - 
Fail	test_submitAudit提交审核 (Test_Case.test_运营用户创建审批.Test_新建用户)

2021-08-27 09:11:42,442    5280     INFO test_runner.py(213) - 
测试结束！
运行时间: 0:00:10.149811
共计执行用例数量：2
执行成功用例数量：1
执行失败用例数量：1
跳过执行用例数量：0
产生异常用例数量：0

2021-08-27 09:17:43,931    7664     INFO test_runner.py(156) - 预计并发线程数：1
2021-08-27 09:17:43,933   27224     INFO result.py(69) - 开始测试： test_applyClient用户资料提交 (Test_Case.test_运营用户创建审批.Test_新建用户)
2021-08-27 09:17:44,087   27224     INFO test_运营用户创建审批.py(28) - 获取到的token为
2021-08-27 09:17:44,119   27224     INFO test_运营用户创建审批.py(35) - 初始化 Session
2021-08-27 09:17:44,167   27224     INFO test_运营用户创建审批.py(45) - 接口请求url为：http://sit-cdms.ynm3k.com/api/client/applyClient
2021-08-27 09:17:49,560   27224     INFO result.py(156) - 测试执行通过： test_applyClient用户资料提交 (Test_Case.test_运营用户创建审批.Test_新建用户)
2021-08-27 09:17:49,560   27224     INFO result.py(90) - 测试结束： test_applyClient用户资料提交 (Test_Case.test_运营用户创建审批.Test_新建用户)
2021-08-27 09:17:49,575   27224     INFO result.py(91) - 耗时： 5.626944541931152
2021-08-27 09:17:49,575   27224     INFO result.py(69) - 开始测试： test_submitAudit提交审核 (Test_Case.test_运营用户创建审批.Test_新建用户)
2021-08-27 09:17:49,611   27224     INFO test_运营用户创建审批.py(28) - 获取到的token为
2021-08-27 09:17:49,750   27224     INFO test_运营用户创建审批.py(218) - 已完成修改WorldCheck的状态为FALSE
2021-08-27 09:17:53,762   27224     INFO test_运营用户创建审批.py(231) - 接口请求url为：http://sit-cdms.ynm3k.com/api/client/submitAudit
2021-08-27 09:17:53,762   27224     INFO test_运营用户创建审批.py(233) - 提交审核获取到的手机号为：16352683968
2021-08-27 09:17:53,870   27224     INFO test_运营用户创建审批.py(236) - 请求数据库cd_clnt_apply_info查询到applyId的值为：()
2021-08-27 09:17:53,945   27224  WARNING result.py(190) - 测试未通过： test_submitAudit提交审核 (Test_Case.test_运营用户创建审批.Test_新建用户)
Traceback (most recent call last):
  File "F:\python\EDDID_CDMS\Test_Case\test_运营用户创建审批.py", line 249, in test_submitAudit提交审核
    self.assertEqual("操作成功", r.json().get("msg"))
AssertionError: '操作成功' != 'JSON invalid format'
- 操作成功
+ JSON invalid format


2021-08-27 09:17:53,945   27224     INFO result.py(90) - 测试结束： test_submitAudit提交审核 (Test_Case.test_运营用户创建审批.Test_新建用户)
2021-08-27 09:17:53,945   27224     INFO result.py(91) - 耗时： 4.369535207748413
2021-08-27 09:17:53,945    7664     INFO test_runner.py(193) - 
Pass	test_applyClient用户资料提交 (Test_Case.test_运营用户创建审批.Test_新建用户)

2021-08-27 09:17:53,945    7664    ERROR test_runner.py(195) - 
Fail	test_submitAudit提交审核 (Test_Case.test_运营用户创建审批.Test_新建用户)

2021-08-27 09:17:53,946    7664     INFO test_runner.py(213) - 
测试结束！
运行时间: 0:00:10.215198
共计执行用例数量：2
执行成功用例数量：1
执行失败用例数量：1
跳过执行用例数量：0
产生异常用例数量：0

2021-08-27 09:20:20,380   18668     INFO test_runner.py(156) - 预计并发线程数：1
2021-08-27 09:20:20,381   26588     INFO result.py(69) - 开始测试： test_applyClient用户资料提交 (Test_Case.test_运营用户创建审批.Test_新建用户)
2021-08-27 09:20:20,381   26588    ERROR result.py(175) - 测试产生错误： test_applyClient用户资料提交 (Test_Case.test_运营用户创建审批.Test_新建用户)
TypeError: setUp() missing 1 required positional argument: 'cls'

2021-08-27 09:20:20,392   26588     INFO result.py(90) - 测试结束： test_applyClient用户资料提交 (Test_Case.test_运营用户创建审批.Test_新建用户)
2021-08-27 09:20:20,408   26588     INFO result.py(91) - 耗时： 0.011001825332641602
2021-08-27 09:20:20,424   26588     INFO result.py(69) - 开始测试： test_submitAudit提交审核 (Test_Case.test_运营用户创建审批.Test_新建用户)
2021-08-27 09:20:20,424   26588    ERROR result.py(175) - 测试产生错误： test_submitAudit提交审核 (Test_Case.test_运营用户创建审批.Test_新建用户)
TypeError: setUp() missing 1 required positional argument: 'cls'

2021-08-27 09:20:20,424   26588     INFO result.py(90) - 测试结束： test_submitAudit提交审核 (Test_Case.test_运营用户创建审批.Test_新建用户)
2021-08-27 09:20:20,424   26588     INFO result.py(91) - 耗时： 0.0
2021-08-27 09:20:20,424   18668    ERROR test_runner.py(195) - 
Error	test_applyClient用户资料提交 (Test_Case.test_运营用户创建审批.Test_新建用户)
Error	test_submitAudit提交审核 (Test_Case.test_运营用户创建审批.Test_新建用户)

2021-08-27 09:20:20,425   18668     INFO test_runner.py(213) - 
测试结束！
运行时间: 0:00:00.251704
共计执行用例数量：2
执行成功用例数量：0
执行失败用例数量：0
跳过执行用例数量：0
产生异常用例数量：2

2021-08-27 09:22:10,392   10476     INFO test_runner.py(156) - 预计并发线程数：1
2021-08-27 09:22:10,393   10708     INFO result.py(69) - 开始测试： test_applyClient用户资料提交 (Test_Case.test_运营用户创建审批.Test_新建用户)
2021-08-27 09:22:10,653   10708     INFO test_运营用户创建审批.py(28) - 获取到的token为
2021-08-27 09:22:10,763   10708    ERROR result.py(175) - 测试产生错误： test_applyClient用户资料提交 (Test_Case.test_运营用户创建审批.Test_新建用户)
Traceback (most recent call last):
  File "F:\python\EDDID_CDMS\Test_Case\test_运营用户创建审批.py", line 31, in test_applyClient用户资料提交
    eddidhost=self.eddidhost
AttributeError: 'Test_新建用户' object has no attribute 'eddidhost'

2021-08-27 09:22:10,779   10708    ERROR result.py(175) - 测试产生错误： test_applyClient用户资料提交 (Test_Case.test_运营用户创建审批.Test_新建用户)
Traceback (most recent call last):
  File "F:\python\EDDID_CDMS\Test_Case\test_运营用户创建审批.py", line 252, in tearDown
    self.s.close()
AttributeError: 'Test_新建用户' object has no attribute 's'

2021-08-27 09:22:10,795   10708     INFO result.py(90) - 测试结束： test_applyClient用户资料提交 (Test_Case.test_运营用户创建审批.Test_新建用户)
2021-08-27 09:22:10,811   10708     INFO result.py(91) - 耗时： 0.40195584297180176
2021-08-27 09:22:10,826   10708     INFO result.py(69) - 开始测试： test_submitAudit提交审核 (Test_Case.test_运营用户创建审批.Test_新建用户)
2021-08-27 09:22:10,846   10708     INFO test_运营用户创建审批.py(28) - 获取到的token为
2021-08-27 09:22:10,846   10708    ERROR result.py(175) - 测试产生错误： test_submitAudit提交审核 (Test_Case.test_运营用户创建审批.Test_新建用户)
Traceback (most recent call last):
  File "F:\python\EDDID_CDMS\Test_Case\test_运营用户创建审批.py", line 213, in test_submitAudit提交审核
    s = self.s
AttributeError: 'Test_新建用户' object has no attribute 's'

2021-08-27 09:22:10,847   10708    ERROR result.py(175) - 测试产生错误： test_submitAudit提交审核 (Test_Case.test_运营用户创建审批.Test_新建用户)
Traceback (most recent call last):
  File "F:\python\EDDID_CDMS\Test_Case\test_运营用户创建审批.py", line 252, in tearDown
    self.s.close()
AttributeError: 'Test_新建用户' object has no attribute 's'

2021-08-27 09:22:10,847   10708     INFO result.py(90) - 测试结束： test_submitAudit提交审核 (Test_Case.test_运营用户创建审批.Test_新建用户)
2021-08-27 09:22:10,847   10708     INFO result.py(91) - 耗时： 0.021164655685424805
2021-08-27 09:22:10,847   10476    ERROR test_runner.py(195) - 
Error	test_applyClient用户资料提交 (Test_Case.test_运营用户创建审批.Test_新建用户)
Error	test_applyClient用户资料提交 (Test_Case.test_运营用户创建审批.Test_新建用户)
Error	test_submitAudit提交审核 (Test_Case.test_运营用户创建审批.Test_新建用户)
Error	test_submitAudit提交审核 (Test_Case.test_运营用户创建审批.Test_新建用户)

2021-08-27 09:22:10,848   10476     INFO test_runner.py(213) - 
测试结束！
运行时间: 0:00:00.649011
共计执行用例数量：2
执行成功用例数量：0
执行失败用例数量：0
跳过执行用例数量：0
产生异常用例数量：2

2021-08-27 09:27:04,907   10936     INFO test_runner.py(156) - 预计并发线程数：1
2021-08-27 09:27:04,908   14700     INFO result.py(69) - 开始测试： test_applyClient用户资料提交 (Test_Case.test_运营用户创建审批.Test_新建用户)
2021-08-27 09:27:04,908   14700     INFO test_运营用户创建审批.py(33) - 获取到的token为
2021-08-27 09:27:05,010   14700    ERROR result.py(175) - 测试产生错误： test_applyClient用户资料提交 (Test_Case.test_运营用户创建审批.Test_新建用户)
Traceback (most recent call last):
  File "F:\python\EDDID_CDMS\Test_Case\test_运营用户创建审批.py", line 36, in test_applyClient用户资料提交
    eddidhost=self.eddidhost
AttributeError: 'Test_新建用户' object has no attribute 'eddidhost'

2021-08-27 09:27:05,040   14700     INFO result.py(90) - 测试结束： test_applyClient用户资料提交 (Test_Case.test_运营用户创建审批.Test_新建用户)
2021-08-27 09:27:05,070   14700     INFO result.py(91) - 耗时： 0.13164997100830078
2021-08-27 09:27:05,070   14700     INFO result.py(69) - 开始测试： test_submitAudit提交审核 (Test_Case.test_运营用户创建审批.Test_新建用户)
2021-08-27 09:27:05,071   14700     INFO test_运营用户创建审批.py(33) - 获取到的token为
2021-08-27 09:27:05,071   14700    ERROR result.py(175) - 测试产生错误： test_submitAudit提交审核 (Test_Case.test_运营用户创建审批.Test_新建用户)
Traceback (most recent call last):
  File "F:\python\EDDID_CDMS\Test_Case\test_运营用户创建审批.py", line 220, in test_submitAudit提交审核
    eddidhost=self.eddidhost
AttributeError: 'Test_新建用户' object has no attribute 'eddidhost'

2021-08-27 09:27:05,071   14700     INFO result.py(90) - 测试结束： test_submitAudit提交审核 (Test_Case.test_运营用户创建审批.Test_新建用户)
2021-08-27 09:27:05,072   14700     INFO result.py(91) - 耗时： 0.0009965896606445312
2021-08-27 09:27:05,072   10936    ERROR test_runner.py(195) - 
Error	test_applyClient用户资料提交 (Test_Case.test_运营用户创建审批.Test_新建用户)
Error	test_submitAudit提交审核 (Test_Case.test_运营用户创建审批.Test_新建用户)

2021-08-27 09:27:05,073   10936     INFO test_runner.py(213) - 
测试结束！
运行时间: 0:00:00.377346
共计执行用例数量：2
执行成功用例数量：0
执行失败用例数量：0
跳过执行用例数量：0
产生异常用例数量：2

2021-08-27 10:14:52,867   14660     INFO test_runner.py(156) - 预计并发线程数：1
2021-08-27 10:14:52,868   27824     INFO result.py(69) - 开始测试： test_applyClient用户资料提交 (Test_Case.test_运营用户创建审批.Test_新建用户)
2021-08-27 10:14:53,068   27824     INFO test_运营用户创建审批.py(33) - 获取到的token为
2021-08-27 10:14:53,132   27824    ERROR result.py(175) - 测试产生错误： test_applyClient用户资料提交 (Test_Case.test_运营用户创建审批.Test_新建用户)
Traceback (most recent call last):
  File "F:\python\EDDID_CDMS\Test_Case\test_运营用户创建审批.py", line 36, in test_applyClient用户资料提交
    eddidhost=self.eddidhost
AttributeError: 'Test_新建用户' object has no attribute 'eddidhost'

2021-08-27 10:14:53,132   27824     INFO result.py(90) - 测试结束： test_applyClient用户资料提交 (Test_Case.test_运营用户创建审批.Test_新建用户)
2021-08-27 10:14:53,148   27824     INFO result.py(91) - 耗时： 0.2643258571624756
2021-08-27 10:14:53,148   27824     INFO result.py(69) - 开始测试： test_submitAudit提交审核 (Test_Case.test_运营用户创建审批.Test_新建用户)
2021-08-27 10:14:53,167   27824     INFO test_运营用户创建审批.py(33) - 获取到的token为
2021-08-27 10:14:53,168   27824    ERROR result.py(175) - 测试产生错误： test_submitAudit提交审核 (Test_Case.test_运营用户创建审批.Test_新建用户)
Traceback (most recent call last):
  File "F:\python\EDDID_CDMS\Test_Case\test_运营用户创建审批.py", line 220, in test_submitAudit提交审核
    eddidhost=self.eddidhost
AttributeError: 'Test_新建用户' object has no attribute 'eddidhost'

2021-08-27 10:14:53,168   27824     INFO result.py(90) - 测试结束： test_submitAudit提交审核 (Test_Case.test_运营用户创建审批.Test_新建用户)
2021-08-27 10:14:53,168   27824     INFO result.py(91) - 耗时： 0.020041704177856445
2021-08-27 10:14:53,168   14660    ERROR test_runner.py(195) - 
Error	test_applyClient用户资料提交 (Test_Case.test_运营用户创建审批.Test_新建用户)
Error	test_submitAudit提交审核 (Test_Case.test_运营用户创建审批.Test_新建用户)

2021-08-27 10:14:53,169   14660     INFO test_runner.py(213) - 
测试结束！
运行时间: 0:00:00.501839
共计执行用例数量：2
执行成功用例数量：0
执行失败用例数量：0
跳过执行用例数量：0
产生异常用例数量：2

2021-08-27 10:16:13,580   21456     INFO test_runner.py(156) - 预计并发线程数：1
2021-08-27 10:16:13,580   11836     INFO result.py(69) - 开始测试： test_applyClient用户资料提交 (Test_Case.test_运营用户创建审批.Test_新建用户)
2021-08-27 10:16:13,673   11836     INFO test_运营用户创建审批.py(33) - 获取到的token为
2021-08-27 10:16:13,780   11836    ERROR result.py(175) - 测试产生错误： test_applyClient用户资料提交 (Test_Case.test_运营用户创建审批.Test_新建用户)
Traceback (most recent call last):
  File "F:\python\EDDID_CDMS\Test_Case\test_运营用户创建审批.py", line 37, in test_applyClient用户资料提交
    idCardNo=self.idCardNo
AttributeError: 'Test_新建用户' object has no attribute 'idCardNo'

2021-08-27 10:16:13,796   11836     INFO result.py(90) - 测试结束： test_applyClient用户资料提交 (Test_Case.test_运营用户创建审批.Test_新建用户)
2021-08-27 10:16:13,828   11836     INFO result.py(91) - 耗时： 0.21445131301879883
2021-08-27 10:16:13,843   11836     INFO result.py(69) - 开始测试： test_submitAudit提交审核 (Test_Case.test_运营用户创建审批.Test_新建用户)
2021-08-27 10:16:13,864   11836     INFO test_运营用户创建审批.py(33) - 获取到的token为
2021-08-27 10:16:14,006   11836     INFO test_运营用户创建审批.py(223) - 已完成修改WorldCheck的状态为FALSE
2021-08-27 10:16:18,019   11836     INFO test_运营用户创建审批.py(236) - 接口请求url为：http://sit-cdms.ynm3k.com/api/client/submitAudit
2021-08-27 10:16:18,019   11836     INFO test_运营用户创建审批.py(238) - 提交审核获取到的手机号为：19928165057
2021-08-27 10:16:18,102   11836     INFO test_运营用户创建审批.py(241) - 请求数据库cd_clnt_apply_info查询到applyId的值为：()
2021-08-27 10:16:18,153   11836  WARNING result.py(190) - 测试未通过： test_submitAudit提交审核 (Test_Case.test_运营用户创建审批.Test_新建用户)
Traceback (most recent call last):
  File "F:\python\EDDID_CDMS\Test_Case\test_运营用户创建审批.py", line 254, in test_submitAudit提交审核
    self.assertEqual("操作成功", r.json().get("msg"))
AssertionError: '操作成功' != 'JSON invalid format'
- 操作成功
+ JSON invalid format


2021-08-27 10:16:18,154   11836     INFO result.py(90) - 测试结束： test_submitAudit提交审核 (Test_Case.test_运营用户创建审批.Test_新建用户)
2021-08-27 10:16:18,154   11836     INFO result.py(91) - 耗时： 4.311550140380859
2021-08-27 10:16:18,154   21456    ERROR test_runner.py(195) - 
Error	test_applyClient用户资料提交 (Test_Case.test_运营用户创建审批.Test_新建用户)
Fail	test_submitAudit提交审核 (Test_Case.test_运营用户创建审批.Test_新建用户)

2021-08-27 10:16:18,155   21456     INFO test_runner.py(213) - 
测试结束！
运行时间: 0:00:04.777433
共计执行用例数量：2
执行成功用例数量：0
执行失败用例数量：1
跳过执行用例数量：0
产生异常用例数量：1

2021-08-27 10:16:51,563   25912     INFO test_runner.py(156) - 预计并发线程数：1
2021-08-27 10:16:51,565    5452     INFO result.py(69) - 开始测试： test_applyClient用户资料提交 (Test_Case.test_运营用户创建审批.Test_新建用户)
2021-08-27 10:16:51,667    5452     INFO test_运营用户创建审批.py(33) - 获取到的token为
2021-08-27 10:16:51,682    5452     INFO test_运营用户创建审批.py(40) - 初始化 Session
2021-08-27 10:16:51,714    5452     INFO test_运营用户创建审批.py(50) - 接口请求url为：http://sit-cdms.ynm3k.com/api/client/applyClient
2021-08-27 10:16:57,044    5452     INFO result.py(156) - 测试执行通过： test_applyClient用户资料提交 (Test_Case.test_运营用户创建审批.Test_新建用户)
2021-08-27 10:16:57,044    5452     INFO result.py(90) - 测试结束： test_applyClient用户资料提交 (Test_Case.test_运营用户创建审批.Test_新建用户)
2021-08-27 10:16:57,060    5452     INFO result.py(91) - 耗时： 5.479364395141602
2021-08-27 10:16:57,060    5452     INFO result.py(69) - 开始测试： test_submitAudit提交审核 (Test_Case.test_运营用户创建审批.Test_新建用户)
2021-08-27 10:16:57,083    5452     INFO test_运营用户创建审批.py(33) - 获取到的token为
2021-08-27 10:16:57,220    5452     INFO test_运营用户创建审批.py(223) - 已完成修改WorldCheck的状态为FALSE
2021-08-27 10:17:01,233    5452     INFO test_运营用户创建审批.py(236) - 接口请求url为：http://sit-cdms.ynm3k.com/api/client/submitAudit
2021-08-27 10:17:01,233    5452     INFO test_运营用户创建审批.py(238) - 提交审核获取到的手机号为：19854642493
2021-08-27 10:17:01,311    5452     INFO test_运营用户创建审批.py(241) - 请求数据库cd_clnt_apply_info查询到applyId的值为：()
2021-08-27 10:17:01,373    5452  WARNING result.py(190) - 测试未通过： test_submitAudit提交审核 (Test_Case.test_运营用户创建审批.Test_新建用户)
Traceback (most recent call last):
  File "F:\python\EDDID_CDMS\Test_Case\test_运营用户创建审批.py", line 254, in test_submitAudit提交审核
    self.assertEqual("操作成功", r.json().get("msg"))
AssertionError: '操作成功' != 'JSON invalid format'
- 操作成功
+ JSON invalid format


2021-08-27 10:17:01,373    5452     INFO result.py(90) - 测试结束： test_submitAudit提交审核 (Test_Case.test_运营用户创建审批.Test_新建用户)
2021-08-27 10:17:01,373    5452     INFO result.py(91) - 耗时： 4.3127899169921875
2021-08-27 10:17:01,373   25912     INFO test_runner.py(193) - 
Pass	test_applyClient用户资料提交 (Test_Case.test_运营用户创建审批.Test_新建用户)

2021-08-27 10:17:01,373   25912    ERROR test_runner.py(195) - 
Fail	test_submitAudit提交审核 (Test_Case.test_运营用户创建审批.Test_新建用户)

2021-08-27 10:17:01,374   25912     INFO test_runner.py(213) - 
测试结束！
运行时间: 0:00:10.020235
共计执行用例数量：2
执行成功用例数量：1
执行失败用例数量：1
跳过执行用例数量：0
产生异常用例数量：0

2021-08-27 10:46:03,305   17448     INFO test_runner.py(156) - 预计并发线程数：1
2021-08-27 10:46:03,307   20528     INFO result.py(69) - 开始测试： test_applyClient用户资料提交 (Test_Case.test_运营用户创建审批.Test_新建用户)
2021-08-27 10:46:03,542   20528    ERROR result.py(175) - 测试产生错误： test_applyClient用户资料提交 (Test_Case.test_运营用户创建审批.Test_新建用户)
Traceback (most recent call last):
  File "F:\python\EDDID_CDMS\Test_Case\test_运营用户创建审批.py", line 26, in setUp
    print("身份证号", idCardNo)
NameError: name 'idCardNo' is not defined

2021-08-27 10:46:03,542   20528     INFO result.py(90) - 测试结束： test_applyClient用户资料提交 (Test_Case.test_运营用户创建审批.Test_新建用户)
2021-08-27 10:46:03,557   20528     INFO result.py(91) - 耗时： 0.23536896705627441
2021-08-27 10:46:03,557   20528     INFO result.py(69) - 开始测试： test_submitAudit提交审核 (Test_Case.test_运营用户创建审批.Test_新建用户)
2021-08-27 10:46:03,577   20528    ERROR result.py(175) - 测试产生错误： test_submitAudit提交审核 (Test_Case.test_运营用户创建审批.Test_新建用户)
Traceback (most recent call last):
  File "F:\python\EDDID_CDMS\Test_Case\test_运营用户创建审批.py", line 26, in setUp
    print("身份证号", idCardNo)
NameError: name 'idCardNo' is not defined

2021-08-27 10:46:03,577   20528     INFO result.py(90) - 测试结束： test_submitAudit提交审核 (Test_Case.test_运营用户创建审批.Test_新建用户)
2021-08-27 10:46:03,577   20528     INFO result.py(91) - 耗时： 0.019841670989990234
2021-08-27 10:46:03,577   17448    ERROR test_runner.py(195) - 
Error	test_applyClient用户资料提交 (Test_Case.test_运营用户创建审批.Test_新建用户)
Error	test_submitAudit提交审核 (Test_Case.test_运营用户创建审批.Test_新建用户)

2021-08-27 10:46:03,579   17448     INFO test_runner.py(213) - 
测试结束！
运行时间: 0:00:00.474730
共计执行用例数量：2
执行成功用例数量：0
执行失败用例数量：0
跳过执行用例数量：0
产生异常用例数量：2

2021-08-27 10:53:44,918   19848     INFO test_runner.py(156) - 预计并发线程数：1
2021-08-27 10:53:44,920   23860     INFO result.py(69) - 开始测试： test_applyClient用户资料提交 (Test_Case.test_运营用户创建审批.Test_新建用户)
2021-08-27 10:53:45,175   23860     INFO test_运营用户创建审批.py(27) - 获取到的token为
2021-08-27 10:53:45,313   23860    ERROR result.py(175) - 测试产生错误： test_applyClient用户资料提交 (Test_Case.test_运营用户创建审批.Test_新建用户)
Traceback (most recent call last):
  File "F:\python\EDDID_CDMS\Test_Case\test_运营用户创建审批.py", line 31, in test_applyClient用户资料提交
    idCardNo=self.idCardNo
AttributeError: 'Test_新建用户' object has no attribute 'idCardNo'

2021-08-27 10:53:45,313   23860     INFO result.py(90) - 测试结束： test_applyClient用户资料提交 (Test_Case.test_运营用户创建审批.Test_新建用户)
2021-08-27 10:53:45,313   23860     INFO result.py(91) - 耗时： 0.3929769992828369
2021-08-27 10:53:45,313   23860     INFO result.py(69) - 开始测试： test_submitAudit提交审核 (Test_Case.test_运营用户创建审批.Test_新建用户)
2021-08-27 10:53:45,333   23860     INFO test_运营用户创建审批.py(27) - 获取到的token为
2021-08-27 10:53:45,334   23860    ERROR result.py(175) - 测试产生错误： test_submitAudit提交审核 (Test_Case.test_运营用户创建审批.Test_新建用户)
Traceback (most recent call last):
  File "F:\python\EDDID_CDMS\Test_Case\test_运营用户创建审批.py", line 213, in test_submitAudit提交审核
    phone=self.phone
AttributeError: 'Test_新建用户' object has no attribute 'phone'

2021-08-27 10:53:45,334   23860     INFO result.py(90) - 测试结束： test_submitAudit提交审核 (Test_Case.test_运营用户创建审批.Test_新建用户)
2021-08-27 10:53:45,334   23860     INFO result.py(91) - 耗时： 0.021107196807861328
2021-08-27 10:53:45,334   19848    ERROR test_runner.py(195) - 
Error	test_applyClient用户资料提交 (Test_Case.test_运营用户创建审批.Test_新建用户)
Error	test_submitAudit提交审核 (Test_Case.test_运营用户创建审批.Test_新建用户)

2021-08-27 10:53:45,335   19848     INFO test_runner.py(213) - 
测试结束！
运行时间: 0:00:00.624909
共计执行用例数量：2
执行成功用例数量：0
执行失败用例数量：0
跳过执行用例数量：0
产生异常用例数量：2

2021-08-27 10:55:26,386   25144     INFO test_runner.py(156) - 预计并发线程数：1
2021-08-27 10:55:26,388    9372     INFO result.py(69) - 开始测试： test_applyClient用户资料提交 (Test_Case.test_运营用户创建审批.Test_新建用户)
2021-08-27 10:55:26,610    9372     INFO test_运营用户创建审批.py(27) - 获取到的token为
2021-08-27 10:55:26,641    9372     INFO test_运营用户创建审批.py(34) - 初始化 Session
2021-08-27 10:55:26,753    9372     INFO test_运营用户创建审批.py(44) - 接口请求url为：http://sit-cdms.ynm3k.com/api/client/applyClient
2021-08-27 10:55:32,028    9372     INFO result.py(156) - 测试执行通过： test_applyClient用户资料提交 (Test_Case.test_运营用户创建审批.Test_新建用户)
2021-08-27 10:55:32,028    9372     INFO result.py(90) - 测试结束： test_applyClient用户资料提交 (Test_Case.test_运营用户创建审批.Test_新建用户)
2021-08-27 10:55:32,028    9372     INFO result.py(91) - 耗时： 5.639939308166504
2021-08-27 10:55:32,044    9372     INFO result.py(69) - 开始测试： test_submitAudit提交审核 (Test_Case.test_运营用户创建审批.Test_新建用户)
2021-08-27 10:55:32,095    9372     INFO test_运营用户创建审批.py(27) - 获取到的token为
2021-08-27 10:55:32,278    9372     INFO test_运营用户创建审批.py(217) - 已完成修改WorldCheck的状态为FALSE
2021-08-27 10:55:36,291    9372     INFO test_运营用户创建审批.py(230) - 接口请求url为：http://sit-cdms.ynm3k.com/api/client/submitAudit
2021-08-27 10:55:36,291    9372     INFO test_运营用户创建审批.py(232) - 提交审核获取到的手机号为：12862199894
2021-08-27 10:55:36,375    9372     INFO test_运营用户创建审批.py(235) - 请求数据库cd_clnt_apply_info查询到applyId的值为：()
2021-08-27 10:55:36,453    9372  WARNING result.py(190) - 测试未通过： test_submitAudit提交审核 (Test_Case.test_运营用户创建审批.Test_新建用户)
Traceback (most recent call last):
  File "F:\python\EDDID_CDMS\Test_Case\test_运营用户创建审批.py", line 248, in test_submitAudit提交审核
    self.assertEqual("操作成功", r.json().get("msg"))
AssertionError: '操作成功' != 'JSON invalid format'
- 操作成功
+ JSON invalid format


2021-08-27 10:55:36,453    9372     INFO result.py(90) - 测试结束： test_submitAudit提交审核 (Test_Case.test_运营用户创建审批.Test_新建用户)
2021-08-27 10:55:36,453    9372     INFO result.py(91) - 耗时： 4.409123420715332
2021-08-27 10:55:36,453   25144     INFO test_runner.py(193) - 
Pass	test_applyClient用户资料提交 (Test_Case.test_运营用户创建审批.Test_新建用户)

2021-08-27 10:55:36,453   25144    ERROR test_runner.py(195) - 
Fail	test_submitAudit提交审核 (Test_Case.test_运营用户创建审批.Test_新建用户)

2021-08-27 10:55:36,454   25144     INFO test_runner.py(213) - 
测试结束！
运行时间: 0:00:10.267956
共计执行用例数量：2
执行成功用例数量：1
执行失败用例数量：1
跳过执行用例数量：0
产生异常用例数量：0

2021-08-27 14:20:50,307   26288     INFO test_runner.py(156) - 预计并发线程数：1
2021-08-27 14:20:50,308   24284     INFO result.py(69) - 开始测试： test_applyClient用户资料提交用例校验 (Test_Case.test_运营用户创建审批12.Test_新建用户)
2021-08-27 14:20:50,309   24284     INFO test_运营用户创建审批12.py(22) - 初始化CreatUser
2021-08-27 14:20:50,467   24284     INFO applyClient用户资料提交.py(29) - 接口请求url为：http://sit-cdms.ynm3k.com/api/client/applyClient
2021-08-27 14:20:50,701   24284     INFO test_运营用户创建审批12.py(28) - 资料提交接口'/api/client/applyClient'的响应结果为:'<Response [200]>'
2021-08-27 14:20:50,794   24284    ERROR result.py(175) - 测试产生错误： test_applyClient用户资料提交用例校验 (Test_Case.test_运营用户创建审批12.Test_新建用户)
Traceback (most recent call last):
  File "F:\python\EDDID_CDMS\Test_Case\test_运营用户创建审批12.py", line 42, in tearDown
    self.s.close()
AttributeError: 'Test_新建用户' object has no attribute 's'

2021-08-27 14:20:50,794   24284     INFO result.py(90) - 测试结束： test_applyClient用户资料提交用例校验 (Test_Case.test_运营用户创建审批12.Test_新建用户)
2021-08-27 14:20:50,809   24284     INFO result.py(91) - 耗时： 0.4847538471221924
2021-08-27 14:20:50,840   24284     INFO result.py(69) - 开始测试： test_submitAudit提交审核 (Test_Case.test_运营用户创建审批12.Test_新建用户)
2021-08-27 14:20:50,840   24284     INFO test_运营用户创建审批12.py(22) - 初始化CreatUser
2021-08-27 14:20:51,342   24284     INFO applyClient用户资料提交.py(195) - 已完成修改WorldCheck的状态为FALSE
2021-08-27 14:20:55,353   24284     INFO applyClient用户资料提交.py(208) - 接口请求url为：http://sit-cdms.ynm3k.com/api/client/submitAudit
2021-08-27 14:20:55,353   24284     INFO applyClient用户资料提交.py(210) - 提交审核获取到的手机号为：12897117758
2021-08-27 14:20:55,905   24284     INFO test_运营用户创建审批12.py(37) - 资料提交接口'/api/client/submitAudit'的响应结果为:'<Response [200]>'
2021-08-27 14:20:55,907   24284  WARNING result.py(190) - 测试未通过： test_submitAudit提交审核 (Test_Case.test_运营用户创建审批12.Test_新建用户)
Traceback (most recent call last):
  File "F:\python\EDDID_CDMS\Test_Case\test_运营用户创建审批12.py", line 39, in test_submitAudit提交审核
    self.assertEqual("操作成功", submitAudit.json().get("msg"))
AssertionError: '操作成功' != '用户没有创建worldCheck或未关联，请检查，稍后操作'
- 操作成功
+ 用户没有创建worldCheck或未关联，请检查，稍后操作


2021-08-27 14:20:55,907   24284    ERROR result.py(175) - 测试产生错误： test_submitAudit提交审核 (Test_Case.test_运营用户创建审批12.Test_新建用户)
Traceback (most recent call last):
  File "F:\python\EDDID_CDMS\Test_Case\test_运营用户创建审批12.py", line 42, in tearDown
    self.s.close()
AttributeError: 'Test_新建用户' object has no attribute 's'

2021-08-27 14:20:55,907   24284     INFO result.py(90) - 测试结束： test_submitAudit提交审核 (Test_Case.test_运营用户创建审批12.Test_新建用户)
2021-08-27 14:20:55,907   24284     INFO result.py(91) - 耗时： 5.067530393600464
2021-08-27 14:20:55,908   26288    ERROR test_runner.py(195) - 
Error	test_applyClient用户资料提交用例校验 (Test_Case.test_运营用户创建审批12.Test_新建用户)
Fail	test_submitAudit提交审核 (Test_Case.test_运营用户创建审批12.Test_新建用户)
Error	test_submitAudit提交审核 (Test_Case.test_运营用户创建审批12.Test_新建用户)

2021-08-27 14:20:55,908   26288     INFO test_runner.py(213) - 
测试结束！
运行时间: 0:00:05.801498
共计执行用例数量：3
执行成功用例数量：0
执行失败用例数量：1
跳过执行用例数量：0
产生异常用例数量：2

2021-08-27 14:21:48,347   18544     INFO test_runner.py(156) - 预计并发线程数：1
2021-08-27 14:21:48,349    9220     INFO result.py(69) - 开始测试： test_applyClient用户资料提交用例校验 (Test_Case.test_运营用户创建审批12.Test_新建用户)
2021-08-27 14:21:48,349    9220     INFO test_运营用户创建审批12.py(21) - 初始化CreatUser
2021-08-27 14:21:48,614    9220     INFO applyClient用户资料提交.py(29) - 接口请求url为：http://sit-cdms.ynm3k.com/api/client/applyClient
2021-08-27 14:21:48,816    9220     INFO test_运营用户创建审批12.py(27) - 资料提交接口'/api/client/applyClient'的响应结果为:'<Response [200]>'
2021-08-27 14:21:48,816    9220     INFO result.py(156) - 测试执行通过： test_applyClient用户资料提交用例校验 (Test_Case.test_运营用户创建审批12.Test_新建用户)
2021-08-27 14:21:48,832    9220     INFO result.py(90) - 测试结束： test_applyClient用户资料提交用例校验 (Test_Case.test_运营用户创建审批12.Test_新建用户)
2021-08-27 14:21:48,832    9220     INFO result.py(91) - 耗时： 0.48326992988586426
2021-08-27 14:21:48,847    9220     INFO result.py(69) - 开始测试： test_submitAudit提交审核 (Test_Case.test_运营用户创建审批12.Test_新建用户)
2021-08-27 14:21:48,847    9220     INFO test_运营用户创建审批12.py(21) - 初始化CreatUser
2021-08-27 14:21:49,316    9220     INFO applyClient用户资料提交.py(195) - 已完成修改WorldCheck的状态为FALSE
2021-08-27 14:21:53,330    9220     INFO applyClient用户资料提交.py(208) - 接口请求url为：http://sit-cdms.ynm3k.com/api/client/submitAudit
2021-08-27 14:21:53,330    9220     INFO applyClient用户资料提交.py(210) - 提交审核获取到的手机号为：16761377312
2021-08-27 14:21:53,532    9220     INFO test_运营用户创建审批12.py(35) - 资料提交接口'/api/client/submitAudit'的响应结果为:'<Response [200]>'
2021-08-27 14:21:53,532    9220     INFO result.py(156) - 测试执行通过： test_submitAudit提交审核 (Test_Case.test_运营用户创建审批12.Test_新建用户)
2021-08-27 14:21:53,532    9220     INFO result.py(90) - 测试结束： test_submitAudit提交审核 (Test_Case.test_运营用户创建审批12.Test_新建用户)
2021-08-27 14:21:53,532    9220     INFO result.py(91) - 耗时： 4.684244394302368
2021-08-27 14:21:53,532   18544     INFO test_runner.py(193) - 
Pass	test_applyClient用户资料提交用例校验 (Test_Case.test_运营用户创建审批12.Test_新建用户)
Pass	test_submitAudit提交审核 (Test_Case.test_运营用户创建审批12.Test_新建用户)

2021-08-27 14:21:53,533   18544     INFO test_runner.py(213) - 
测试结束！
运行时间: 0:00:05.384644
共计执行用例数量：2
执行成功用例数量：2
执行失败用例数量：0
跳过执行用例数量：0
产生异常用例数量：0

2021-08-27 14:35:38,666   17240     INFO test_runner.py(156) - 预计并发线程数：1
2021-08-27 14:35:38,668   17608     INFO result.py(69) - 开始测试： test_applyClient用户资料提交用例校验 (Test_Case.test_运营用户创建审批12.Test_新建用户)
2021-08-27 14:35:38,668   17608     INFO test_运营用户创建审批12.py(21) - 初始化CreatUser
2021-08-27 14:35:38,852   17608     INFO applyClient用户资料提交.py(19) - 获取到的token为
2021-08-27 14:35:38,868   17608     INFO applyClient用户资料提交.py(188) - 提交申请单时注册用户手机号码为：16692815525
2021-08-27 14:35:39,123   17608     INFO applyClient用户资料提交.py(190) - 接口'http://sit-cdms.ynm3k.com/api/client/applyClient'的响应结果为：'{"code":"0000","msg":"操作成功","data":null}'
2021-08-27 14:35:39,123   17608     INFO result.py(156) - 测试执行通过： test_applyClient用户资料提交用例校验 (Test_Case.test_运营用户创建审批12.Test_新建用户)
2021-08-27 14:35:39,139   17608     INFO result.py(90) - 测试结束： test_applyClient用户资料提交用例校验 (Test_Case.test_运营用户创建审批12.Test_新建用户)
2021-08-27 14:35:39,139   17608     INFO result.py(91) - 耗时： 0.47076845169067383
2021-08-27 14:35:39,139   17608     INFO result.py(69) - 开始测试： test_submitAudit提交审核 (Test_Case.test_运营用户创建审批12.Test_新建用户)
2021-08-27 14:35:39,139   17608     INFO test_运营用户创建审批12.py(21) - 初始化CreatUser
2021-08-27 14:35:39,600   17608     INFO applyClient用户资料提交.py(195) - 已完成修改WorldCheck的状态为FALSE
2021-08-27 14:35:43,605   17608     INFO applyClient用户资料提交.py(203) - 获取到的token为
2021-08-27 14:35:43,605   17608     INFO applyClient用户资料提交.py(211) - 提交审核获取到的手机号为：16692815525
2021-08-27 14:35:43,733   17608     INFO applyClient用户资料提交.py(223) - 提交审核接口'http://sit-cdms.ynm3k.com/api/client/submitAudit'的响应结果为:'{"code":"CDMS_04040","msg":"用户没有创建worldCheck或未关联，请检查，稍后操作","data":""}'
2021-08-27 14:35:43,733   17608  WARNING result.py(190) - 测试未通过： test_submitAudit提交审核 (Test_Case.test_运营用户创建审批12.Test_新建用户)
Traceback (most recent call last):
  File "F:\python\EDDID_CDMS\Test_Case\test_运营用户创建审批12.py", line 37, in test_submitAudit提交审核
    self.assertEqual("操作成功", submitAudit.json().get("msg"))
AssertionError: '操作成功' != '用户没有创建worldCheck或未关联，请检查，稍后操作'
- 操作成功
+ 用户没有创建worldCheck或未关联，请检查，稍后操作


2021-08-27 14:35:43,733   17608     INFO result.py(90) - 测试结束： test_submitAudit提交审核 (Test_Case.test_运营用户创建审批12.Test_新建用户)
2021-08-27 14:35:43,733   17608     INFO result.py(91) - 耗时： 4.594277620315552
2021-08-27 14:35:43,733   17240     INFO test_runner.py(193) - 
Pass	test_applyClient用户资料提交用例校验 (Test_Case.test_运营用户创建审批12.Test_新建用户)

2021-08-27 14:35:43,734   17240    ERROR test_runner.py(195) - 
Fail	test_submitAudit提交审核 (Test_Case.test_运营用户创建审批12.Test_新建用户)

2021-08-27 14:35:43,735   17240     INFO test_runner.py(213) - 
测试结束！
运行时间: 0:00:05.266241
共计执行用例数量：2
执行成功用例数量：1
执行失败用例数量：1
跳过执行用例数量：0
产生异常用例数量：0

2021-08-27 14:40:55,421   13568     INFO test_runner.py(156) - 预计并发线程数：1
2021-08-27 14:40:55,422   18620     INFO result.py(69) - 开始测试： test_applyClient用户资料提交用例校验 (Test_Case.test_运营用户创建审批12.Test_新建用户)
2021-08-27 14:40:55,422   18620     INFO test_运营用户创建审批12.py(21) - 初始化CreatUser
2021-08-27 14:40:55,646   18620     INFO applyClient用户资料提交.py(19) - 获取到的token为
2021-08-27 14:40:55,693   18620     INFO applyClient用户资料提交.py(188) - 提交申请单时注册用户手机号码为：11492363009
2021-08-27 14:40:55,943   18620     INFO applyClient用户资料提交.py(190) - 接口'http://sit-cdms.ynm3k.com/api/client/applyClient'的响应结果为：'{"code":"0000","msg":"操作成功","data":null}'
2021-08-27 14:41:00,975   18620     INFO test_运营用户创建审批12.py(42) - 接口请求完成后，等待系统处理数据，等待5秒
2021-08-27 14:41:00,975   18620     INFO result.py(156) - 测试执行通过： test_applyClient用户资料提交用例校验 (Test_Case.test_运营用户创建审批12.Test_新建用户)
2021-08-27 14:41:00,990   18620     INFO result.py(90) - 测试结束： test_applyClient用户资料提交用例校验 (Test_Case.test_运营用户创建审批12.Test_新建用户)
2021-08-27 14:41:01,006   18620     INFO result.py(91) - 耗时： 5.5681304931640625
2021-08-27 14:41:01,022   18620     INFO result.py(69) - 开始测试： test_submitAudit提交审核 (Test_Case.test_运营用户创建审批12.Test_新建用户)
2021-08-27 14:41:01,022   18620     INFO test_运营用户创建审批12.py(21) - 初始化CreatUser
2021-08-27 14:41:01,524   18620     INFO applyClient用户资料提交.py(195) - 已完成修改WorldCheck的状态为FALSE
2021-08-27 14:41:05,527   18620     INFO applyClient用户资料提交.py(203) - 获取到的token为
2021-08-27 14:41:05,527   18620     INFO applyClient用户资料提交.py(211) - 提交审核获取到的手机号为：11492363009
2021-08-27 14:41:05,763   18620     INFO applyClient用户资料提交.py(223) - 提交审核接口'http://sit-cdms.ynm3k.com/api/client/submitAudit'的响应结果为:'{"code":"0000","msg":"操作成功","data":null}'
2021-08-27 14:41:10,773   18620     INFO test_运营用户创建审批12.py(42) - 接口请求完成后，等待系统处理数据，等待5秒
2021-08-27 14:41:10,773   18620     INFO result.py(156) - 测试执行通过： test_submitAudit提交审核 (Test_Case.test_运营用户创建审批12.Test_新建用户)
2021-08-27 14:41:10,773   18620     INFO result.py(90) - 测试结束： test_submitAudit提交审核 (Test_Case.test_运营用户创建审批12.Test_新建用户)
2021-08-27 14:41:10,773   18620     INFO result.py(91) - 耗时： 9.751163244247437
2021-08-27 14:41:10,773   13568     INFO test_runner.py(193) - 
Pass	test_applyClient用户资料提交用例校验 (Test_Case.test_运营用户创建审批12.Test_新建用户)
Pass	test_submitAudit提交审核 (Test_Case.test_运营用户创建审批12.Test_新建用户)

2021-08-27 14:41:10,774   13568     INFO test_runner.py(213) - 
测试结束！
运行时间: 0:00:15.572131
共计执行用例数量：2
执行成功用例数量：2
执行失败用例数量：0
跳过执行用例数量：0
产生异常用例数量：0

2021-08-27 14:42:41,294   25728     INFO test_runner.py(156) - 预计并发线程数：1
2021-08-27 14:42:41,296   14344     INFO result.py(69) - 开始测试： test_applyClient用户资料提交用例校验 (Test_Case.test_运营用户创建审批12.Test_新建用户)
2021-08-27 14:42:41,296   14344     INFO test_运营用户创建审批12.py(21) - 初始化CreatUser
2021-08-27 14:42:41,427   14344     INFO applyClient用户资料提交.py(19) - 获取到的token为:DFBE3D9E2326647F4AEDD5B9E14CBD2E7AC79FFD18F78973
2021-08-27 14:42:41,473   14344     INFO applyClient用户资料提交.py(188) - 提交申请单时注册用户手机号码为：16760036201
2021-08-27 14:42:41,775   14344     INFO applyClient用户资料提交.py(190) - 接口'http://sit-cdms.ynm3k.com/api/client/applyClient'的响应结果为：'{"code":"0000","msg":"操作成功","data":null}'
2021-08-27 14:42:46,798   14344     INFO test_运营用户创建审批12.py(42) - 接口请求完成后，等待系统处理数据，等待5秒
2021-08-27 14:42:46,814   14344     INFO result.py(156) - 测试执行通过： test_applyClient用户资料提交用例校验 (Test_Case.test_运营用户创建审批12.Test_新建用户)
2021-08-27 14:42:46,814   14344     INFO result.py(90) - 测试结束： test_applyClient用户资料提交用例校验 (Test_Case.test_运营用户创建审批12.Test_新建用户)
2021-08-27 14:42:46,814   14344     INFO result.py(91) - 耗时： 5.518261909484863
2021-08-27 14:42:46,814   14344     INFO result.py(69) - 开始测试： test_submitAudit提交审核 (Test_Case.test_运营用户创建审批12.Test_新建用户)
2021-08-27 14:42:46,814   14344     INFO test_运营用户创建审批12.py(21) - 初始化CreatUser
2021-08-27 14:42:47,291   14344     INFO applyClient用户资料提交.py(195) - 已完成修改WorldCheck的状态为FALSE
2021-08-27 14:42:51,306   14344     INFO applyClient用户资料提交.py(203) - 获取到的token为:DFBE3D9E2326647F4AEDD5B9E14CBD2E7AC79FFD18F78973
2021-08-27 14:42:51,306   14344     INFO applyClient用户资料提交.py(211) - 提交审核获取到的手机号为：16760036201
2021-08-27 14:42:51,582   14344     INFO applyClient用户资料提交.py(223) - 提交审核接口'http://sit-cdms.ynm3k.com/api/client/submitAudit'的响应结果为:'{"code":"0000","msg":"操作成功","data":null}'
2021-08-27 14:42:56,599   14344     INFO test_运营用户创建审批12.py(42) - 接口请求完成后，等待系统处理数据，等待5秒
2021-08-27 14:42:56,599   14344     INFO result.py(156) - 测试执行通过： test_submitAudit提交审核 (Test_Case.test_运营用户创建审批12.Test_新建用户)
2021-08-27 14:42:56,599   14344     INFO result.py(90) - 测试结束： test_submitAudit提交审核 (Test_Case.test_运营用户创建审批12.Test_新建用户)
2021-08-27 14:42:56,599   14344     INFO result.py(91) - 耗时： 9.784134864807129
2021-08-27 14:42:56,599   25728     INFO test_runner.py(193) - 
Pass	test_applyClient用户资料提交用例校验 (Test_Case.test_运营用户创建审批12.Test_新建用户)
Pass	test_submitAudit提交审核 (Test_Case.test_运营用户创建审批12.Test_新建用户)

2021-08-27 14:42:56,600   25728     INFO test_runner.py(213) - 
测试结束！
运行时间: 0:00:15.507141
共计执行用例数量：2
执行成功用例数量：2
执行失败用例数量：0
跳过执行用例数量：0
产生异常用例数量：0

2021-08-27 14:45:05,688   17656     INFO test_runner.py(156) - 预计并发线程数：1
2021-08-27 14:45:05,689   11468     INFO result.py(69) - 开始测试： test_applyClient用户资料提交用例校验 (Test_Case.test_运营用户创建审批.Test_新建用户)
2021-08-27 14:45:05,689   11468     INFO test_运营用户创建审批.py(21) - 初始化CreatUser
2021-08-27 14:45:05,830   11468     INFO applyClient用户资料提交.py(19) - 获取到的token为:DFBE3D9E2326647F7F40642834F444AE7AC79FFD18F78973
2021-08-27 14:45:05,830   11468     INFO applyClient用户资料提交.py(188) - 提交申请单时注册用户手机号码为：10305770198
2021-08-27 14:45:06,084   11468     INFO applyClient用户资料提交.py(190) - 接口'http://sit-cdms.ynm3k.com/api/client/applyClient'的响应结果为：'{"code":"0000","msg":"操作成功","data":null}'
2021-08-27 14:45:10,112   11468     INFO test_运营用户创建审批.py(42) - 接口请求完成后，等待系统处理数据，等待4秒
2021-08-27 14:45:10,112   11468     INFO result.py(156) - 测试执行通过： test_applyClient用户资料提交用例校验 (Test_Case.test_运营用户创建审批.Test_新建用户)
2021-08-27 14:45:10,128   11468     INFO result.py(90) - 测试结束： test_applyClient用户资料提交用例校验 (Test_Case.test_运营用户创建审批.Test_新建用户)
2021-08-27 14:45:10,143   11468     INFO result.py(91) - 耗时： 4.438156366348267
2021-08-27 14:45:10,158   11468     INFO result.py(69) - 开始测试： test_submitAudit提交审核 (Test_Case.test_运营用户创建审批.Test_新建用户)
2021-08-27 14:45:10,158   11468     INFO test_运营用户创建审批.py(21) - 初始化CreatUser
2021-08-27 14:45:10,615   11468     INFO applyClient用户资料提交.py(195) - 已完成修改WorldCheck的状态为FALSE
2021-08-27 14:45:14,618   11468     INFO applyClient用户资料提交.py(203) - 获取到的token为:DFBE3D9E2326647F7F40642834F444AE7AC79FFD18F78973
2021-08-27 14:45:14,618   11468     INFO applyClient用户资料提交.py(211) - 提交审核获取到的手机号为：10305770198
2021-08-27 14:45:14,781   11468     INFO applyClient用户资料提交.py(223) - 提交审核接口'http://sit-cdms.ynm3k.com/api/client/submitAudit'的响应结果为:'{"code":"0000","msg":"操作成功","data":null}'
2021-08-27 14:45:18,794   11468     INFO test_运营用户创建审批.py(42) - 接口请求完成后，等待系统处理数据，等待4秒
2021-08-27 14:45:18,794   11468     INFO result.py(156) - 测试执行通过： test_submitAudit提交审核 (Test_Case.test_运营用户创建审批.Test_新建用户)
2021-08-27 14:45:18,794   11468     INFO result.py(90) - 测试结束： test_submitAudit提交审核 (Test_Case.test_运营用户创建审批.Test_新建用户)
2021-08-27 14:45:18,794   11468     INFO result.py(91) - 耗时： 8.635523080825806
2021-08-27 14:45:18,794   17656     INFO test_runner.py(193) - 
Pass	test_applyClient用户资料提交用例校验 (Test_Case.test_运营用户创建审批.Test_新建用户)
Pass	test_submitAudit提交审核 (Test_Case.test_运营用户创建审批.Test_新建用户)

2021-08-27 14:45:18,795   17656     INFO test_runner.py(213) - 
测试结束！
运行时间: 0:00:13.304824
共计执行用例数量：2
执行成功用例数量：2
执行失败用例数量：0
跳过执行用例数量：0
产生异常用例数量：0

